Workbook

Sheet Tolerance log
A1: Spinney — Bullnose board calliper log, 27 Oct 2026
A2: Millboard Ashwood bullnose (MEBB360H), 19 boards measured by calliper (mm). Readings are the handwritten record of 27/10/26; crossed-out values resolved by Ryan: #1 right back 31.65, #2 left back 31.73, #7 left width 150.63, #11 left back 31.95.
A4: Nominal width (mm) | C4: 150 | D4: Assumed nominals — edit if the manufacturer figures differ; all deviations and pass/fail below recalculate.
A5: Nominal thickness (mm) | C5: 32
A6: Tolerance, ± (mm) — manufacturer guideline | C6: 2
A8: Board # | B8: Batch | C8: Status | D8: Left width | E8: Left back | F8: Left bullnose | G8: Right width | H8: Right back | I8: Right bullnose | J8: Δ L width | K8: Δ L back | L8: Δ L bullnose | M8: Δ R width | N8: Δ R back | O8: Δ R bullnose | P8: Worst |Δ| | Q8: Result
A9: 1 | B9: — | C9: Fixed in place (fence edge) | D9: 149.48 | E9: 31.23 | F9: 30.28 | G9: 150.12 | H9: 31.65 | I9: 31.29 | J9: =D9-$C$4 -> -0.52 | K9: =E9-$C$5 -> -0.77 | L9: =F9-$C$5 -> -1.72 | M9: =G9-$C$4 -> 0.12 | N9: =H9-$C$5 -> -0.35 | O9: =I9-$C$5 -> -0.71 | P9: =MAX(ABS(J9),ABS(K9),ABS(L9),ABS(M9),ABS(N9),ABS(O9)) -> 1.72 | Q9: =IF(P9<=$C$6,"Pass","FAIL") -> Pass
A10: 2 | B10: — | C10: Fixed in place (fence edge) | D10: 151.27 | E10: 31.73 | F10: 30.5 | G10: 150.99 | H10: 31.73 | I10: 31 | J10: =D10-$C$4 -> 1.27 | K10: =E10-$C$5 -> -0.27 | L10: =F10-$C$5 -> -1.5 | M10: =G10-$C$4 -> 0.99 | N10: =H10-$C$5 -> -0.27 | O10: =I10-$C$5 -> -1 | P10: =MAX(ABS(J10),ABS(K10),ABS(L10),ABS(M10),ABS(N10),ABS(O10)) -> 1.5 | Q10: =IF(P10<=$C$6,"Pass","FAIL") -> Pass
A11: 3 | B11: — | C11: Fixed in place (fence edge) | D11: 151.04 | E11: 31.76 | F11: 30.7 | G11: 150.04 | H11: 30.7 | I11: 32.02 | J11: =D11-$C$4 -> 1.04 | K11: =E11-$C$5 -> -0.24 | L11: =F11-$C$5 -> -1.3 | M11: =G11-$C$4 -> 0.04 | N11: =H11-$C$5 -> -1.3 | O11: =I11-$C$5 -> 0.02 | P11: =MAX(ABS(J11),ABS(K11),ABS(L11),ABS(M11),ABS(N11),ABS(O11)) -> 1.3 | Q11: =IF(P11<=$C$6,"Pass","FAIL") -> Pass
A12: 4 | B12: — | C12: Fixed in place (fence edge) | D12: 151.21 | E12: 30.97 | F12: 31.17 | G12: 150.5 | H12: 31.31 | I12: 31.42 | J12: =D12-$C$4 -> 1.21 | K12: =E12-$C$5 -> -1.03 | L12: =F12-$C$5 -> -0.83 | M12: =G12-$C$4 -> 0.5 | N12: =H12-$C$5 -> -0.69 | O12: =I12-$C$5 -> -0.58 | P12: =MAX(ABS(J12),ABS(K12),ABS(L12),ABS(M12),ABS(N12),ABS(O12)) -> 1.21 | Q12: =IF(P12<=$C$6,"Pass","FAIL") -> Pass
A13: 5 | B13: — | C13: Fixed in place (fence edge) | D13: 150.64 | E13: 31.04 | F13: 31.05 | G13: 149.64 | H13: 31.04 | I13: 31.05 | J13: =D13-$C$4 -> 0.64 | K13: =E13-$C$5 -> -0.96 | L13: =F13-$C$5 -> -0.95 | M13: =G13-$C$4 -> -0.36 | N13: =H13-$C$5 -> -0.96 | O13: =I13-$C$5 -> -0.95 | P13: =MAX(ABS(J13),ABS(K13),ABS(L13),ABS(M13),ABS(N13),ABS(O13)) -> 0.96 | Q13: =IF(P13<=$C$6,"Pass","FAIL") -> Pass
A14: 6 | B14: — | C14: Fixed in place (fence edge) | D14: 151.08 | E14: 31.6 | F14: 30.87 | G14: 151.24 | H14: 31.6 | I14: 31.47 | J14: =D14-$C$4 -> 1.08 | K14: =E14-$C$5 -> -0.4 | L14: =F14-$C$5 -> -1.13 | M14: =G14-$C$4 -> 1.24 | N14: =H14-$C$5 -> -0.4 | O14: =I14-$C$5 -> -0.53 | P14: =MAX(ABS(J14),ABS(K14),ABS(L14),ABS(M14),ABS(N14),ABS(O14)) -> 1.24 | Q14: =IF(P14<=$C$6,"Pass","FAIL") -> Pass
A15: 7 | B15: 1011 030626 | C15: Uncut | D15: 150.63 | E15: 31.06 | F15: 31.07 | G15: 149.46 | H15: 30.75 | I15: 31.34 | J15: =D15-$C$4 -> 0.63 | K15: =E15-$C$5 -> -0.94 | L15: =F15-$C$5 -> -0.93 | M15: =G15-$C$4 -> -0.54 | N15: =H15-$C$5 -> -1.25 | O15: =I15-$C$5 -> -0.66 | P15: =MAX(ABS(J15),ABS(K15),ABS(L15),ABS(M15),ABS(N15),ABS(O15)) -> 1.25 | Q15: =IF(P15<=$C$6,"Pass","FAIL") -> Pass
A16: 8 | B16: 1008 030626 | C16: Uncut | D16: 150.64 | E16: 32.45 | F16: 31.45 | G16: 149.33 | H16: 31.48 | I16: 31.31 | J16: =D16-$C$4 -> 0.64 | K16: =E16-$C$5 -> 0.45 | L16: =F16-$C$5 -> -0.55 | M16: =G16-$C$4 -> -0.67 | N16: =H16-$C$5 -> -0.52 | O16: =I16-$C$5 -> -0.69 | P16: =MAX(ABS(J16),ABS(K16),ABS(L16),ABS(M16),ABS(N16),ABS(O16)) -> 0.69 | Q16: =IF(P16<=$C$6,"Pass","FAIL") -> Pass
A17: 9 | B17: 1830 03082026 | C17: Uncut | D17: 150.69 | E17: 31.76 | F17: 31.86 | G17: 149.49 | H17: 31.86 | I17: 32.17 | J17: =D17-$C$4 -> 0.69 | K17: =E17-$C$5 -> -0.24 | L17: =F17-$C$5 -> -0.14 | M17: =G17-$C$4 -> -0.51 | N17: =H17-$C$5 -> -0.14 | O17: =I17-$C$5 -> 0.17 | P17: =MAX(ABS(J17),ABS(K17),ABS(L17),ABS(M17),ABS(N17),ABS(O17)) -> 0.69 | Q17: =IF(P17<=$C$6,"Pass","FAIL") -> Pass
A18: 10 | B18: 1739 03082026 | C18: Uncut | D18: 151.4 | E18: 30.89 | F18: 31.81 | G18: 150.7 | H18: 31.74 | I18: 31.87 | J18: =D18-$C$4 -> 1.4 | K18: =E18-$C$5 -> -1.11 | L18: =F18-$C$5 -> -0.19 | M18: =G18-$C$4 -> 0.7 | N18: =H18-$C$5 -> -0.26 | O18: =I18-$C$5 -> -0.13 | P18: =MAX(ABS(J18),ABS(K18),ABS(L18),ABS(M18),ABS(N18),ABS(O18)) -> 1.4 | Q18: =IF(P18<=$C$6,"Pass","FAIL") -> Pass
A19: 11 | B19: 1739 03082026 | C19: Uncut | D19: 150.25 | E19: 31.95 | F19: 31.47 | G19: 150.11 | H19: 32.37 | I19: 31.27 | J19: =D19-$C$4 -> 0.25 | K19: =E19-$C$5 -> -0.05 | L19: =F19-$C$5 -> -0.53 | M19: =G19-$C$4 -> 0.11 | N19: =H19-$C$5 -> 0.37 | O19: =I19-$C$5 -> -0.73 | P19: =MAX(ABS(J19),ABS(K19),ABS(L19),ABS(M19),ABS(N19),ABS(O19)) -> 0.73 | Q19: =IF(P19<=$C$6,"Pass","FAIL") -> Pass
A20: 12 | B20: 0741 030626 | C20: Uncut | D20: 151.04 | E20: 31.4 | F20: 31.1 | G20: 150.35 | H20: 31.58 | I20: 31.52 | J20: =D20-$C$4 -> 1.04 | K20: =E20-$C$5 -> -0.6 | L20: =F20-$C$5 -> -0.9 | M20: =G20-$C$4 -> 0.35 | N20: =H20-$C$5 -> -0.42 | O20: =I20-$C$5 -> -0.48 | P20: =MAX(ABS(J20),ABS(K20),ABS(L20),ABS(M20),ABS(N20),ABS(O20)) -> 1.04 | Q20: =IF(P20<=$C$6,"Pass","FAIL") -> Pass
... A27: 19 | B27: — (Diagonal to upper level) | C27: Fixed in place (diagonal to upper level) | D27: 150.17 | E27: 31.33 | F27: 31.87 | G27: 149.99 | H27: 31.33 | I27: 31.29 | J27: =D27-$C$4 -> 0.17 | K27: =E27-$C$5 -> -0.67 | L27: =F27-$C$5 -> -0.13 | M27: =G27-$C$4 -> -0.01 | N27: =H27-$C$5 -> -0.67 | O27: =I27-$C$5 -> -0.71 | P27: =MAX(ABS(J27),ABS(K27),ABS(L27),ABS(M27),ABS(N27),ABS(O27)) -> 0.71 | Q27: =IF(P27<=$C$6,"Pass","FAIL") -> Pass
A29: Summary
A30: Boards measured | D30: =COUNTA(A9:A27) -> 19
A31: Boards passing | D31: =COUNTIF(Q9:Q27,"Pass") -> 19
A32: Boards failing | D32: =COUNTIF(Q9:Q27,"FAIL") -> 0
A33: Largest deviation from nominal (mm) | D33: =MAX(P9:P27) -> 1.72
A34: Smallest width reading (mm) | D34: =MIN(D9:D27,G9:G27) -> 149.33
A35: Largest width reading (mm) | D35: =MAX(D9:D27,G9:G27) -> 151.4
A36: Smallest thickness reading (mm) | D36: =MIN(E9:F27,H9:I27) -> 30.28
A37: Largest thickness reading (mm) | D37: =MAX(E9:F27,H9:I27) -> 32.45
A39: Boards #1–6, #18 and #19 carry no batch code: they were measured before being cut to shape and fixed. Boards #7–17 are uncut with batch code underneath. 18 full-length equivalents in total (7 cut + 11 uncut).

Sheet Laying order
A1: Optimal laying order — 11 uncut bullnose boards, one continuous edge, laid left to right
A3: Method: a joint is the RIGHT end of one board meeting the LEFT end of the next. Mismatch = absolute difference between those two readings. Every possible order of the 11 boards was tested (exact, not a heuristic); the order with the smallest total mismatch wins. First board joins on its right only; last board joins on its left only.
A4: Four scenarios: optimise for width, bullnose face thickness, back-edge thickness, or all three together (worst of the three at each joint). Boards are laid in the orientation measured (left end to the left); no board is turned round. Boards already fixed (#1–6, #18, #19) are excluded.
A5: Mismatch figures are live formulas against the Tolerance log sheet. Lower is better; a smaller mismatch means less visible step at the joint.
A7: Summary — best order by scenario
A8: Scenario | B8: Best laying order (board numbers, left → right) | C8: Total mismatch (mm) | D8: Worst single joint (mm) | E8: Typical random order (mm) | F8: Improvement vs random
A9: Width | B9: 10 → 12 → 7 → 9 → 11 → 14 → 15 → 16 → 13 → 17 → 8 | C9: =B30 -> 4.75 | D9: =D30 -> 1.23 | E9: 7.09 | F9: =1-C9/E9 -> 0.33004231
A10: Bullnose face | B10: 17 → 7 → 14 → 15 → 8 → 12 → 11 → 13 → 16 → 10 → 9 | C10: =B77 -> 0.95 | D10: =D77 -> 0.24 | E10: 3.85 | F10: =1-C10/E10 -> 0.75324675
A11: Back edge | B11: 7 → 10 → 9 → 11 → 8 → 12 → 14 → 16 → 17 → 15 → 13 | C11: =B124 -> 1.09 | D11: =D124 -> 0.29 | E11: 5.04 | F11: =1-C11/E11 -> 0.78373016
A12: Combined (worst of the three) | B12: 10 → 9 → 11 → 8 → 13 → 12 → 16 → 15 → 14 → 7 → 17 | C12: =B171 -> 5.2 | D12: =D171 -> 0.83 | E12: 9 | F12: =1-C12/E12 -> 0.42222222
A13: "Typical random order" is the average total mismatch over all possible orders, for comparison. Combined scenario scores each joint by its worst of the three differences.
A16: Scenario: Width
A17: Best order | B17: 10 → 12 → 7 → 9 → 11 → 14 → 15 → 16 → 13 → 17 → 8
A18: Position | B18: Board # | C18: Batch | D18: Right end → Next board left end | E18: Next board # | F18: Mismatch at joint (mm)
A19: 1 | B19: 10 | C19: =INDEX('Tolerance log'!$B$9:$B$27,MATCH(B19,'Tolerance log'!$A$9:$A$27,0)) -> 1739 03082026 | D19: =TEXT(INDEX('Tolerance log'!$G$9:$G$27,MATCH(B19,'Tolerance log'!$A$9:$A$27,0)),"0.00")&" → "&TEXT(INDEX('Tolerance log'!$D$9:$D$27,MATCH(E19,'Tolerance log'!$A$9:$A$27,0)),"0.00") -> 150.70 → 151.04 | E19: 12 | F19: =ABS(INDEX('Tolerance log'!$G$9:$G$27,MATCH(B19,'Tolerance log'!$A$9:$A$27,0))-INDEX('Tolerance log'!$D$9:$D$27,MATCH(E19,'Tolerance log'!$A$9:$A$27,0))) -> 0.34
A20: 2 | B20: 12 | C20: =INDEX('Tolerance log'!$B$9:$B$27,MATCH(B20,'Tolerance log'!$A$9:$A$27,0)) -> 0741 030626 | D20: =TEXT(INDEX('Tolerance log'!$G$9:$G$27,MATCH(B20,'Tolerance log'!$A$9:$A$27,0)),"0.00")&" → "&TEXT(INDEX('Tolerance log'!$D$9:$D$27,MATCH(E20,'Tolerance log'!$A$9:$A$27,0)),"0.00") -> 150.35 → 150.63 | E20: 7 | F20: =ABS(INDEX('Tolerance log'!$G$9:$G$27,MATCH(B20,'Tolerance log'!$A$9:$A$27,0))-INDEX('Tolerance log'!$D$9:$D$27,MATCH(E20,'Tolerance log'!$A$9:$A$27,0))) -> 0.28
A21: 3 | B21: 7 | C21: =INDEX('Tolerance log'!$B$9:$B$27,MATCH(B21,'Tolerance log'!$A$9:$A$27,0)) -> 1011 030626 | D21: =TEXT(INDEX('Tolerance log'!$G$9:$G$27,MATCH(B21,'Tolerance log'!$A$9:$A$27,0)),"0.00")&" → "&TEXT(INDEX('Tolerance log'!$D$9:$D$27,MATCH(E21,'Tolerance log'!$A$9:$A$27,0)),"0.00") -> 149.46 → 150.69 | E21: 9 | F21: =ABS(INDEX('Tolerance log'!$G$9:$G$27,MATCH(B21,'Tolerance log'!$A$9:$A$27,0))-INDEX('Tolerance log'!$D$9:$D$27,MATCH(E21,'Tolerance log'!$A$9:$A$27,0))) -> 1.23
A22: 4 | B22: 9 | C22: =INDEX('Tolerance log'!$B$9:$B$27,MATCH(B22,'Tolerance log'!$A$9:$A$27,0)) -> 1830 03082026 | D22: =TEXT(INDEX('Tolerance log'!$G$9:$G$27,MATCH(B22,'Tolerance log'!$A$9:$A$27,0)),"0.00")&" → "&TEXT(INDEX('Tolerance log'!$D$9:$D$27,MATCH(E22,'Tolerance log'!$A$9:$A$27,0)),"0.00") -> 149.49 → 150.25 | E22: 11 | F22: =ABS(INDEX('Tolerance log'!$G$9:$G$27,MATCH(B22,'Tolerance log'!$A$9:$A$27,0))-INDEX('Tolerance log'!$D$9:$D$27,MATCH(E22,'Tolerance log'!$A$9:$A$27,0))) -> 0.76
A23: 5 | B23: 11 | C23: =INDEX('Tolerance log'!$B$9:$B$27,MATCH(B23,'Tolerance log'!$A$9:$A$27,0)) -> 1739 03082026 | D23: =TEXT(INDEX('Tolerance log'!$G$9:$G$27,MATCH(B23,'Tolerance log'!$A$9:$A$27,0)),"0.00")&" → "&TEXT(INDEX('Tolerance log'!$D$9:$D$27,MATCH(E23,'Tolerance log'!$A$9:$A$27,0)),"0.00") -> 150.11 → 150.40 | E23: 14 | F23: =ABS(INDEX('Tolerance log'!$G$9:$G$27,MATCH(B23,'Tolerance log'!$A$9:$A$27,0))-INDEX('Tolerance log'!$D$9:$D$27,MATCH(E23,'Tolerance log'!$A$9:$A$27,0))) -> 0.29
A24: 6 | B24: 14 | C24: =INDEX('Tolerance log'!$B$9:$B$27,MATCH(B24,'Tolerance log'!$A$9:$A$27,0)) -> 1012 030626 | D24: =TEXT(INDEX('Tolerance log'!$G$9:$G$27,MATCH(B24,'Tolerance log'!$A$9:$A$27,0)),"0.00")&" → "&TEXT(INDEX('Tolerance log'!$D$9:$D$27,MATCH(E24,'Tolerance log'!$A$9:$A$27,0)),"0.00") -> 150.25 → 150.45 | E24: 15 | F24: =ABS(INDEX('Tolerance log'!$G$9:$G$27,MATCH(B24,'Tolerance log'!$A$9:$A$27,0))-INDEX('Tolerance log'!$D$9:$D$27,MATCH(E24,'Tolerance log'!$A$9:$A$27,0))) -> 0.2
A25: 7 | B25: 15 | C25: =INDEX('Tolerance log'!$B$9:$B$27,MATCH(B25,'Tolerance log'!$A$9:$A$27,0)) -> 1020 030626 | D25: =TEXT(INDEX('Tolerance log'!$G$9:$G$27,MATCH(B25,'Tolerance log'!$A$9:$A$27,0)),"0.00")&" → "&TEXT(INDEX('Tolerance log'!$D$9:$D$27,MATCH(E25,'Tolerance log'!$A$9:$A$27,0)),"0.00") -> 150.25 → 150.61 | E25: 16 | F25: =ABS(INDEX('Tolerance log'!$G$9:$G$27,MATCH(B25,'Tolerance log'!$A$9:$A$27,0))-INDEX('Tolerance log'!$D$9:$D$27,MATCH(E25,'Tolerance log'!$A$9:$A$27,0))) -> 0.36
A26: 8 | B26: 16 | C26: =INDEX('Tolerance log'!$B$9:$B$27,MATCH(B26,'Tolerance log'!$A$9:$A$27,0)) -> 1025 030626 | D26: =TEXT(INDEX('Tolerance log'!$G$9:$G$27,MATCH(B26,'Tolerance log'!$A$9:$A$27,0)),"0.00")&" → "&TEXT(INDEX('Tolerance log'!$D$9:$D$27,MATCH(E26,'Tolerance log'!$A$9:$A$27,0)),"0.00") -> 149.65 → 149.72 | E26: 13 | F26: =ABS(INDEX('Tolerance log'!$G$9:$G$27,MATCH(B26,'Tolerance log'!$A$9:$A$27,0))-INDEX('Tolerance log'!$D$9:$D$27,MATCH(E26,'Tolerance log'!$A$9:$A$27,0))) -> 0.07
A27: 9 | B27: 13 | C27: =INDEX('Tolerance log'!$B$9:$B$27,MATCH(B27,'Tolerance log'!$A$9:$A$27,0)) -> 1029 030626 | D27: =TEXT(INDEX('Tolerance log'!$G$9:$G$27,MATCH(B27,'Tolerance log'!$A$9:$A$27,0)),"0.00")&" → "&TEXT(INDEX('Tolerance log'!$D$9:$D$27,MATCH(E27,'Tolerance log'!$A$9:$A$27,0)),"0.00") -> 150.28 → 150.29 | E27: 17 | F27: =ABS(INDEX('Tolerance log'!$G$9:$G$27,MATCH(B27,'Tolerance log'!$A$9:$A$27,0))-INDEX('Tolerance log'!$D$9:$D$27,MATCH(E27,'Tolerance log'!$A$9:$A$27,0))) -> 0.01
A28: 10 | B28: 17 | C28: =INDEX('Tolerance log'!$B$9:$B$27,MATCH(B28,'Tolerance log'!$A$9:$A$27,0)) -> 1018 030626 | D28: =TEXT(INDEX('Tolerance log'!$G$9:$G$27,MATCH(B28,'Tolerance log'!$A$9:$A$27,0)),"0.00")&" → "&TEXT(INDEX('Tolerance log'!$D$9:$D$27,MATCH(E28,'Tolerance log'!$A$9:$A$27,0)),"0.00") -> 149.43 → 150.64 | E28: 8 | F28: =ABS(INDEX('Tolerance log'!$G$9:$G$27,MATCH(B28,'Tolerance log'!$A$9:$A$27,0))-INDEX('Tolerance log'!$D$9:$D$27,MATCH(E28,'Tolerance log'!$A$9:$A$27,0))) -> 1.21
A29: 11 | B29: 8 | C29: =INDEX('Tolerance log'!$B$9:$B$27,MATCH(B29,'Tolerance log'!$A$9:$A$27,0)) -> 1008 030626 | D29: (end of edge)
A30: Total mismatch | B30: =SUM(F19:F28) -> 4.75 | C30: Worst joint | D30: =MAX(F19:F28) -> 1.23
A32: 2nd-best alternative | B32: 10 → 12 → 7 → 9 → 11 → 14 → 15 → 16 → 17 → 13 → 8
A33: Position | B33: Board # | C33: Batch | D33: Right end → Next board left end | E33: Next board # | F33: Mismatch at joint (mm)
A34: 1 | B34: 10 | C34: =INDEX('Tolerance log'!$B$9:$B$27,MATCH(B34,'Tolerance log'!$A$9:$A$27,0)) -> 1739 03082026 | D34: =TEXT(INDEX('Tolerance log'!$G$9:$G$27,MATCH(B34,'Tolerance log'!$A$9:$A$27,0)),"0.00")&" → "&TEXT(INDEX('Tolerance log'!$D$9:$D$27,MATCH(E34,'Tolerance log'!$A$9:$A$27,0)),"0.00") -> 150.70 → 151.04 | E34: 12 | F34: =ABS(INDEX('Tolerance log'!$G$9:$G$27,MATCH(B34,'Tolerance log'!$A$9:$A$27,0))-INDEX('Tolerance log'!$D$9:$D$27,MATCH(E34,'Tolerance log'!$A$9:$A$27,0))) -> 0.34
A35: 2 | B35: 12 | C35: =INDEX('Tolerance log'!$B$9:$B$27,MATCH(B35,'Tolerance log'!$A$9:$A$27,0)) -> 0741 030626 | D35: =TEXT(INDEX('Tolerance log'!$G$9:$G$27,MATCH(B35,'Tolerance log'!$A$9:$A$27,0)),"0.00")&" → "&TEXT(INDEX('Tolerance log'!$D$9:$D$27,MATCH(E35,'Tolerance log'!$A$9:$A$27,0)),"0.00") -> 150.35 → 150.63 | E35: 7 | F35: =ABS(INDEX('Tolerance log'!$G$9:$G$27,MATCH(B35,'Tolerance log'!$A$9:$A$27,0))-INDEX('Tolerance log'!$D$9:$D$27,MATCH(E35,'Tolerance log'!$A$9:$A$27,0))) -> 0.28
A36: 3 | B36: 7 | C36: =INDEX('Tolerance log'!$B$9:$B$27,MATCH(B36,'Tolerance log'!$A$9:$A$27,0)) -> 1011 030626 | D36: =TEXT(INDEX('Tolerance log'!$G$9:$G$27,MATCH(B36,'Tolerance log'!$A$9:$A$27,0)),"0.00")&" → "&TEXT(INDEX('Tolerance log'!$D$9:$D$27,MATCH(E36,'Tolerance log'!$A$9:$A$27,0)),"0.00") -> 149.46 → 150.69 | E36: 9 | F36: =ABS(INDEX('Tolerance log'!$G$9:$G$27,MATCH(B36,'Tolerance log'!$A$9:$A$27,0))-INDEX('Tolerance log'!$D$9:$D$27,MATCH(E36,'Tolerance log'!$A$9:$A$27,0))) -> 1.23
A37: 4 | B37: 9 | C37: =INDEX('Tolerance log'!$B$9:$B$27,MATCH(B37,'Tolerance log'!$A$9:$A$27,0)) -> 1830 03082026 | D37: =TEXT(INDEX('Tolerance log'!$G$9:$G$27,MATCH(B37,'Tolerance log'!$A$9:$A$27,0)),"0.00")&" → "&TEXT(INDEX('Tolerance log'!$D$9:$D$27,MATCH(E37,'Tolerance log'!$A$9:$A$27,0)),"0.00") -> 149.49 → 150.25 | E37: 11 | F37: =ABS(INDEX('Tolerance log'!$G$9:$G$27,MATCH(B37,'Tolerance log'!$A$9:$A$27,0))-INDEX('Tolerance log'!$D$9:$D$27,MATCH(E37,'Tolerance log'!$A$9:$A$27,0))) -> 0.76
A38: 5 | B38: 11 | C38: =INDEX('Tolerance log'!$B$9:$B$27,MATCH(B38,'Tolerance log'!$A$9:$A$27,0)) -> 1739 03082026 | D38: =TEXT(INDEX('Tolerance log'!$G$9:$G$27,MATCH(B38,'Tolerance log'!$A$9:$A$27,0)),"0.00")&" → "&TEXT(INDEX('Tolerance log'!$D$9:$D$27,MATCH(E38,'Tolerance log'!$A$9:$A$27,0)),"0.00") -> 150.11 → 150.40 | E38: 14 | F38: =ABS(INDEX('Tolerance log'!$G$9:$G$27,MATCH(B38,'Tolerance log'!$A$9:$A$27,0))-INDEX('Tolerance log'!$D$9:$D$27,MATCH(E38,'Tolerance log'!$A$9:$A$27,0))) -> 0.29
A39: 6 | B39: 14 | C39: =INDEX('Tolerance log'!$B$9:$B$27,MATCH(B39,'Tolerance log'!$A$9:$A$27,0)) -> 1012 030626 | D39: =TEXT(INDEX('Tolerance log'!$G$9:$G$27,MATCH(B39,'Tolerance log'!$A$9:$A$27,0)),"0.00")&" → "&TEXT(INDEX('Tolerance log'!$D$9:$D$27,MATCH(E39,'Tolerance log'!$A$9:$A$27,0)),"0.00") -> 150.25 → 150.45 | E39: 15 | F39: =ABS(INDEX('Tolerance log'!$G$9:$G$27,MATCH(B39,'Tolerance log'!$A$9:$A$27,0))-INDEX('Tolerance log'!$D$9:$D$27,MATCH(E39,'Tolerance log'!$A$9:$A$27,0))) -> 0.2
A40: 7 | B40: 15 | C40: =INDEX('Tolerance log'!$B$9:$B$27,MATCH(B40,'Tolerance log'!$A$9:$A$27,0)) -> 1020 030626 | D40: =TEXT(INDEX('Tolerance log'!$G$9:$G$27,MATCH(B40,'Tolerance log'!$A$9:$A$27,0)),"0.00")&" → "&TEXT(INDEX('Tolerance log'!$D$9:$D$27,MATCH(E40,'Tolerance log'!$A$9:$A$27,0)),"0.00") -> 150.25 → 150.61 | E40: 16 | F40: =ABS(INDEX('Tolerance log'!$G$9:$G$27,MATCH(B40,'Tolerance log'!$A$9:$A$27,0))-INDEX('Tolerance log'!$D$9:$D$27,MATCH(E40,'Tolerance log'!$A$9:$A$27,0))) -> 0.36
A41: 8 | B41: 16 | C41: =INDEX('Tolerance log'!$B$9:$B$27,MATCH(B41,'Tolerance log'!$A$9:$A$27,0)) -> 1025 030626 | D41: =TEXT(INDEX('Tolerance log'!$G$9:$G$27,MATCH(B41,'Tolerance log'!$A$9:$A$27,0)),"0.00")&" → "&TEXT(INDEX('Tolerance log'!$D$9:$D$27,MATCH(E41,'Tolerance log'!$A$9:$A$27,0)),"0.00") -> 149.65 → 150.29 | E41: 17 | F41: =ABS(INDEX('Tolerance log'!$G$9:$G$27,MATCH(B41,'Tolerance log'!$A$9:$A$27,0))-INDEX('Tolerance log'!$D$9:$D$27,MATCH(E41,'Tolerance log'!$A$9:$A$27,0))) -> 0.64
A42: 9 | B42: 17 | C42: =INDEX('Tolerance log'!$B$9:$B$27,MATCH(B42,'Tolerance log'!$A$9:$A$27,0)) -> 1018 030626 | D42: =TEXT(INDEX('Tolerance log'!$G$9:$G$27,MATCH(B42,'Tolerance log'!$A$9:$A$27,0)),"0.00")&" → "&TEXT(INDEX('Tolerance log'!$D$9:$D$27,MATCH(E42,'Tolerance log'!$A$9:$A$27,0)),"0.00") -> 149.43 → 149.72 | E42: 13 | F42: =ABS(INDEX('Tolerance log'!$G$9:$G$27,MATCH(B42,'Tolerance log'!$A$9:$A$27,0))-INDEX('Tolerance log'!$D$9:$D$27,MATCH(E42,'Tolerance log'!$A$9:$A$27,0))) -> 0.29
A43: 10 | B43: 13 | C43: =INDEX('Tolerance log'!$B$9:$B$27,MATCH(B43,'Tolerance log'!$A$9:$A$27,0)) -> 1029 030626 | D43: =TEXT(INDEX('Tolerance log'!$G$9:$G$27,MATCH(B43,'Tolerance log'!$A$9:$A$27,0)),"0.00")&" → "&TEXT(INDEX('Tolerance log'!$D$9:$D$27,MATCH(E43,'Tolerance log'!$A$9:$A$27,0)),"0.00") -> 150.28 → 150.64 | E43: 8 | F43: =ABS(INDEX('Tolerance log'!$G$9:$G$27,MATCH(B43,'Tolerance log'!$A$9:$A$27,0))-INDEX('Tolerance log'!$D$9:$D$27,MATCH(E43,'Tolerance log'!$A$9:$A$27,0))) -> 0.36
A44: 11 | B44: 8 | C44: =INDEX('Tolerance log'!$B$9:$B$27,MATCH(B44,'Tolerance log'!$A$9:$A$27,0)) -> 1008 030626 | D44: (end of edge)
A45: Total mismatch | B45: =SUM(F34:F43) -> 4.75 | C45: Worst joint | D45: =MAX(F34:F43) -> 1.23
...
