Workbook

Sheet Summary
A1: Spinney External Works — Budget Summary
A2: Last updated: | B2: 46317 | C2: All figures gross (as payable). Invoiced / Paid pull automatically from the Invoice Register; Contingency remaining pulls from the Drawdown sheet.
A4: Cost centre | B4: Supplier | C4: Committed £ | D4: Invoiced £ | E4: Paid £ | F4: Remaining vs committed £ | G4: Notes
A5: Decking materials (V4) | B5: V4 Wood Flooring Ltd | C5: 32228.99 | D5: =SUMIF('Invoice Register'!$B:$B,$A5,'Invoice Register'!$F:$F) -> 32228.99 | E5: =SUMIFS('Invoice Register'!$F:$F,'Invoice Register'!$B:$B,$A5,'Invoice Register'!$G:$G,"<>") -> 32228.99 | F5: =C5-D5 -> 0 | G5: Order amended to all Ashwood + flexible bullnose (1 Jul). PAID IN FULL 9 Jul, ref V4FQ-15584. 25% restocking on over-ordering — unlikely given curved design + offcuts project, but noted. A separate, later V4 order (£5,322.74, quote #QUO-0031, 29 Sep) for the expanded shed-area/fence-move decking scope is tracked under Contingency (named purpose #24), not here — see that sheet.
A6: Decking labour | B6: LG Building and Roofing Ltd | C6: 17600 | D6: =SUMIF('Invoice Register'!$B:$B,$A6,'Invoice Register'!$F:$F) -> 8400 | E6: =SUMIFS('Invoice Register'!$F:$F,'Invoice Register'!$B:$B,$A6,'Invoice Register'!$G:$G,"<>") -> 8400 | F6: =C6-D6 -> 9200 | G6: Labour £17,600 (no VAT). Stage 1 (£4,400) invoiced/paid 20 Aug, full price. Two cash instalments since (£2,000 each, 4 Sep + 18 Sep) — 10% discount applies to both, retiring £2,222.22 of quoted value each. £8,400 cash paid to date, equivalent to £8,844.44 of quoted value — £8,755.56 quoted value remaining. Rubbish removal (£1,200) transferred 10 Aug to pooled skip fund — see that row, not double-counted here. The separate extra labour for the curves and additional deck (INV-0293, £1,850, 9 Oct) sits under Contingency, not here; it does not change the £8,755.56 remaining.
A7: Contingency | B7: — | C7: 5000 | D7: =SUMIF('Invoice Register'!$B:$B,$A7,'Invoice Register'!$F:$F) -> 16659.97 | E7: =SUMIFS('Invoice Register'!$F:$F,'Invoice Register'!$B:$B,$A7,'Invoice Register'!$G:$G,"<>") -> 16659.97 | F7: =C7-D7 -> -11659.97 | G7: Covers: fence move/repair labour; soakaway fix before decking; drainage by garage; extra curved-decking labour; cement & bricks; coping condensation-prep (£250, PAID 14 Aug via bank transfer, INV-0288). Luke's labour drawn from this pot attracts the 10% discount (extended 20 Jul) — note the condensation-prep item was paid by bank transfer, not cash, so discount doesn't apply there. See Contingency Drawdown sheet. NEW 29 Sep — named purpose #24: V4 materials for the expanded shed-area/fence-move decking scope, £5,322.74, PAID by phone. This single draw alone takes Contingency well over the £5,000 cap — flagged, not hidden, same treatment as the Rubbish removal pooled overage. NEW 3 Oct — named purposes #25–#30: six further TP invoices (£1,093.57). The £500 paid to TP on 11 Sep cleared #5 (£108.14), £247.01 of #6 and £144.85 of Luke's invoices for other jobs (not project spend — netted off in the agreed TP settlement). TP account SETTLED: £2,313.89 paid by card 5 Oct, Luke repaid £144.85 on 6 Oct (net £2,169.04). See TP Account tab. NEW 9 Oct — LG INV-0293 £1,850 (curves £800 = purpose #4; additional deck £1,050 = purpose #32), paid by bank transfer. PENDING, not yet drawn: additional lead work ~£200 (purpose #31, Luke's estimate 2 Oct, not started) — to come from Contingency once invoiced. Luke's further extended-deck labour is not yet agreed or logged. NEW 13 Oct — named purpose #33: Toolstation saw blades and drill bits £84.97 (bought by Luke on his card, repaid in cash 13 Oct). PENDING, not yet drawn: whole-house soft wash £1,200 cash (Gorgeous Cleaning Services, purpose #34, from Mon 19 Oct). NEW 17 Oct — LG INV-0294 (£1,350, no VAT, paid by bank transfer): £350 driveway channel (named purpose #35, new scope 'Driveway channel') + £1,000 extra decking labour (named purpose #36). Still PENDING, not yet drawn: whole-house soft wash £1,200 cash (purpose #34, from Mon 19 Oct), lead work ~£200 (purpose #31, work done 16 Oct, awaiting invoice) and V4 screw top-up #3, now invoiced at £47.22 and unpaid (purpose #15, replaces the £141.66 estimate). NEW 20 Oct — named purpose #37: pipe lagging for the outside tap/pipework, £177.58 (Buy Insulation Online, paid by Ryan's card; scope Shared / site-wide). NEW 22 Oct — named purpose #38: V4 QUO-0040 £1,268 (materials to complete the decking substructure, delivered Mon 19 Oct, paid by card 22 Oct). The soft wash (#34) was completed and paid in cash (£1,200) on Mon 19 Oct. Also to be drawn from Contingency, no estimates yet: Revolutional Electrical (cables under the decking for the new shed area and the extended-deck lighting; call-out charge 22 Oct), the new shed (still to be ordered) and three new grates by the side of the house (extra work).
A8: Chimney repair | B8: LG Building and Roofing Ltd | C8: 4700 | D8: =SUMIF('Invoice Register'!$B:$B,$A8,'Invoice Register'!$F:$F) -> 4700.01 | E8: =SUMIFS('Invoice Register'!$F:$F,'Invoice Register'!$B:$B,$A8,'Invoice Register'!$G:$G,"<>") -> 4700.01 | F8: =C8-D8 -> -0.01 | G8: Quoted 2 Jun: £3,200 labour (invoiced full price, INV-0286) + £1,500 scaffold share. Cowl upgrade (£62.90) and TP account materials reclassified out 17 Aug — see Contingency and Materials (pooled) rows. This is now a clean quote-vs-actual labour figure.
A9: Coping stones repair | B9: LG Building and Roofing Ltd | C9: 5310 | D9: =SUMIF('Invoice Register'!$B:$B,$A9,'Invoice Register'!$F:$F) -> 5310 | E9: =SUMIFS('Invoice Register'!$F:$F,'Invoice Register'!$B:$B,$A9,'Invoice Register'!$G:$G,"<>") -> 5310 | F9: =C9-D9 -> 0 | G9: Quoted 3 Jun: £3,800 labour, confirmed 7 Aug as £3,610 blended (50% cash @10% disc. + 50% invoiced) + £1,700 scaffold share. Condensation-prep (£276.42) and TP account materials share (£277.29) reclassified out — see Contingency and Materials (pooled) rows. RISK: coping-stone damage on removal could substantially increase cost.
A10: Materials (pooled) | B10: Merchant trade accounts | C10: 1130 | D10: =SUMIF('Invoice Register'!$B:$B,$A10,'Invoice Register'!$F:$F) -> 1120.69 | E10: =SUMIFS('Invoice Register'!$F:$F,'Invoice Register'!$B:$B,$A10,'Invoice Register'!$G:$G,"<>") -> 1120.69 | F10: =C10-D10 -> 9.31 | G10: Pooled chimney (£480) + coping (£650) materials budget — decision 20 Jul. Purchased via merchant trade accounts (Dry Lining Supplies, Travis Perkins etc.), cleared on receipts. Detail on Materials Receipts sheet.
A11: Rubbish removal (pooled skips) | B11: Skip Hire Comparison Ltd / future providers | C11: 1360 | D11: =SUMIF('Invoice Register'!$B:$B,$A11,'Invoice Register'!$F:$F) -> 1460 | E11: =SUMIFS('Invoice Register'!$F:$F,'Invoice Register'!$B:$B,$A11,'Invoice Register'!$G:$G,"<>") -> 1460 | F11: =C11-D11 -> -100 | G11: Transferred 10 Aug from chimney/coping/decking rubbish-removal quotes (£80+£80+£1,200). Original skip (Skip Hire Comparison Ltd) cancelled 11 Aug, refunded — replaced same-day by Elmbridge Mini Skips (2 skips, £780 total, settled 12 Aug). Provisional — more skips expected, especially during decking. Detail on Skip Hire Log sheet. £40 Roofline works rubbish removal is expected but not yet incurred — not counted above; if incurred the pool would be £140 over.
A12: Roofline works | B12: LG Building and Roofing Ltd | C12: 2100 | D12: =SUMIF('Invoice Register'!$B:$B,$A12,'Invoice Register'!$F:$F) -> 1984.93 | E12: =SUMIFS('Invoice Register'!$F:$F,'Invoice Register'!$B:$B,$A12,'Invoice Register'!$G:$G,"<>") -> 1984.93 | F12: =C12-D12 -> 115.07 | G12: Own scope, own budget (estimate 4 Sep, £2,140 — unchanged; started 29 Sep, all roofline works complete Fri 16 Oct, including the lead flashing) — gutter replacement, fascia/soffit extension, slate replacement, barge board trim. Replaces the earlier 'gutters included in Luke's price' arrangement (back-gutter realignment and front gutters/tile repairs): on 4 Oct Gantt tasks 1.5, 1.7 and 3.2 were merged into one 'Roofline works' task (1.5). The estimate has no front-of-house gutters, and front tile repairs are covered by 'replace various broken slates'. Budget £2,100 = £1,600 labour (no VAT) + £150 scaffold tower + £350 materials; the £40 rubbish removal in the quote sits in the pooled Rubbish removal fund (not yet incurred). The tower was not needed (Luke used his own ladder) and that £150 benefit offsets the £40.40 of additional materials: net £109.60 under budget. LABOUR: INV-0291 £1,600 (2 Oct) confirmed correct and PAID 3 Oct by bank transfer, full price. MATERIALS: Graham SI19670857 £256.78 (£260 cash, paid 29 Sep); Graham SI19687572 £9.74 + TFP 0001458493 £78.01 (£90 cash) and TFP 0001458792 £40.40 (all paid in cash 2 Oct). This row shows £1,984.93 (invoices only); Cost Lines and Budget vs Actual use £1,990.40 actual, which includes £5.47 of coin top-ups. Additional lead work (~£200, Gantt task 1.5a, part of Gate 2) is outside this budget — see Contingency.
A13: Core project (Luke's ~£56,800 outline) | C13: =C5+C6+C7 -> 54828.99 | D13: =D5+D6+D7 -> 57288.96 | E13: =E5+E6+E7 -> 57288.96 | F13: =F5+F6+F7 -> -2459.97
A14: Chimney + coping incl. pooled materials | C14: =C8+C9+C10 -> 11140 | D14: =D8+D9+D10 -> 11130.7 | E14: =E8+E9+E10 -> 11130.7 | F14: =F8+F9+F10 -> 9.3
A15: PROJECT TOTAL | C15: =C11+C12+C13+C14 -> 69428.99 | D15: =D11+D12+D13 -> 60733.89 | E15: =E11+E12+E13 -> 60733.89 | F15: =F11+F12+F13 -> -2444.9
A16: Contingency remaining: | B16: ='Contingency Drawdown'!$D$4 -> -11659.97
A18: Cost centre = which budget pays · Scope = what it was for (see Scope View tab) · 'Decking materials (V4)' = V4 orders only; Travis Perkins and other decking-related materials sit in Contingency.
A20: Decking labour — quoted-value position (10% cash discount applied)
A21: Quoted labour, stages 1–4 | C21: =C6 -> 17600 | G21: Luke's quote for the main decking labour.
A22: Quoted value covered to date | C22: =SUMIFS('Invoice Register'!$F:$F,'Invoice Register'!$B:$B,"Decking labour",'Invoice Register'!$H:$H,"Bank transfer")+SUMIFS('Invoice Register'!$F:$F,'Invoice Register'!$B:$B,"Decking labour",'Invoice Register'!$H:$H,"Cash*")/0.9 -> 8844.4444 | G22: Bank payments at face value; cash payments ÷ 0.9 because of the 10% cash discount (e.g. £2,000 cash covers £2,222.22 of quoted value).
A23: Quoted value REMAINING | C23: =C21-C22 -> 8755.5556 | G23: This is the figure to use. It matches Luke's own workings (£8,756). The 'Remaining' column above (£9,200) is a plain cash subtraction, and the older tracker view that showed £11,200 pre-dated the 18 Sep instalment.

Sheet Budget vs Actual
A1: Spinney External Works — Budget vs Actual
A2: Snapshot as of 22 Oct 2026 (Week 13) — refresh narrative each batched update session; table figures pull from Summary sheet.
A4: Snapshot
A5: Week 13 — Contingency is well over cap: £16,659.97 drawn and paid against the £5,000 pot (£11,659.97 over). The main driver is the £5,322.74 V4 materials order for the expanded shed-area/fence-move decking scope (named purpose #24, paid by card 29 Sep). Since the last update, the whole-house soft wash by Gorgeous Cleaning Services (£1,200 cash) was completed and paid on Mon 19 Oct, pipe lagging for the outside tap/pipework (£177.58, Buy Insulation Online, paid by Ryan's card 20 Oct) was drawn from Contingency, and LG INV-0294 (£1,350, paid by bank transfer 17 Oct) added £350 for the driveway channel (half a day, Luke and Max) and £1,000 of extra decking labour. Nothing is invoiced but unpaid in the Register. Still to come from Contingency: the ~£200 additional lead work (done 16 Oct, awaiting invoice) and the V4 screw top-up #3, now invoiced at £47.22 and unpaid. The further V4 delivery to complete the decking substructure (QUO-0040, £1,268) arrived Mon 19 Oct and was paid by card on 22 Oct. Also to come from Contingency, with no estimates yet: Revolutional Electrical's cabling and extended-deck lighting (call-out charge 22 Oct), the new shed (still to be ordered) and three new grates by the side of the house (extra work). The total as spent/committed is now £2,251.06 over the overall budget. Chimney and coping are complete and settled. All roofline works were completed Fri 16 Oct, including the lead flashing.
A7: • Chimney | B7: COMPLETE (Gate 1, 18 Aug) — £0 variance, labour invoiced at the full quoted £3,200, no discount applied (non-cash terms).
A8: • Coping | B8: COMPLETE (Gate 1, 18 Aug) — £190 UNDER quote, half the labour was settled in cash at the agreed 10% discount, the other half invoiced at full price.
A9: • Decking (labour + V4 materials) | B9: Materials fully paid to the V4 proforma exactly (£32,228.99 — unchanged; the new £5,322.74 V4 order sits under Contingency, see below, not here). Labour: Stage 1 (£4,400) invoiced full price, plus two £2,000 cash instalments (4 Sep, 18 Sep, 10% discount each) — £8,844.44 quoted-value equivalent paid so far, £8,755.56 remaining across future stages.
A10: • Scaffold (pooled, chimney + coping combined) | B10: £0 variance — this was never split-quoted per workstream, just one £3,200 job (£2,000 paid on erection, £1,200 due on strike). Treating it as its own pooled line avoids implying a false per-workstream comparison.
A11: • Materials (pooled, chimney + coping) | B11: Back under the £1,130 cap — a £72.23 refund from Dry Lining Supplies (unused monocouche + other returned items) landed 19 Aug, more than offsetting the earlier £62.90 overage from pooling Luke's Travis Perkins account purchases.
A12: • Rubbish removal (pooled, all 3 workstreams) | B12: £1,460 spent against the £1,360 pool — £100 over. That is £780 for the two Elmbridge skips plus £680 for the old decking substructure wood collection, which was charged per trip and came in well above the £350 estimate. The skips and wood removal served chimney, coping and the soakaway/decking-prep groundworks, so the spend can't be attributed cleanly to one workstream. A further £40 for the Roofline works rubbish removal is expected but not yet incurred; if it is, the pool would be £140 over. Flagged, not hidden.
A13: • Roofline works (new) | B13: £1,600 labour + £150 scaffold tower + £350 materials = £2,100 budget (quote £2,140 unchanged; the £40 rubbish removal sits in the pooled fund). Started 29 Sep, all roofline works completed Fri 16 Oct, including the lead flashing. Labour INV-0291 (£1,600) paid 3 Oct by bank transfer. The tower was not needed — Luke used his ladder — and that £150 benefit offsets £40.40 of additional materials (four invoices, £390.40 cash, all reimbursed to Luke): net £109.60 under budget, actual £1,990.40. Additional lead work (~£200) will come from Contingency.
A14: • Contingency | B14: £16,659.97 drawn and PAID against the £5,000 pot — £11,659.97 OVER CAP. Main driver: £5,322.74 V4 materials order (purpose #24, paid 29 Sep). Travis Perkins invoices were settled 5 Oct, LG INV-0293 (£1,850) was paid 9 Oct, whole-house soft wash (£1,200 cash, purpose #34, 19 Oct), Toolstation tools (£84.97, purpose #33) were repaid 13 Oct and LG INV-0294 (£1,350: driveway channel £350 + extra decking labour £1,000) was paid 17 Oct and pipe lagging (£177.58, purpose #37) on 20 Oct, and V4 QUO-0040 (£1,268, purpose #38) on 22 Oct. Flagged, not hidden. Pending, not yet drawn: ~£200 additional lead work (purpose #31) and V4 screw top-up #3 (£47.22 invoiced, unpaid).
A16: Budget vs Actual — detail
A17: Cost centre | B17: Quote / Budget £ | C17: Actual £ | D17: Variance £ | E17: Note
A18: Chimney (labour) | B18: 3200 | C18: 3200 | D18: 0 | E18: Invoiced full price (INV-0286) — non-cash, no discount
A19: Coping (labour) | B19: 3800 | C19: 3610 | D19: -190 | E19: 50% cash @10% disc. + 50% invoiced — favourable
A20: Decking (labour) | B20: 17600 | C20: 8400 | D20: -9200 | E20: Stage 1 (£4,400 invoiced) + two £2,000 cash instalments (4 Sep, 18 Sep, 10% discount each) — £8,844.44 quoted value retired, £8,755.56 remaining, mix of future cash/invoice TBC.
A21: Decking materials (V4) | B21: 32228.99 | C21: 32228.99 | D21: 0 | E21: Proforma matched exactly, paid in full 9 Jul
A22: Scaffold (pooled, chimney+coping) | B22: 3200 | C22: 3200 | D22: 0 | E22: Never split-quoted — one combined job. £2,000 paid, £1,200 due on strike
A23: Materials (pooled, chimney+coping) | B23: 1130 | C23: 1120.69 | D23: -9.31 | E23: Back under the £1,130 cap after a £72.23 refund from Dry Lining Supplies (unused monocouche + other returned items) landed 19 Aug — was £62.92 over before the refund.
A24: Rubbish removal (pooled, all 3 workstreams) | B24: 1360 | C24: 1460 | D24: 100 | E24: £100 OVER the £1,360 cap — the wood removal correction (£350 est. → £680 actual, charged per trip) pushed it over. Flagged, not hidden; cap left as-is per the same approach used for Materials pooled. Plus £40 expected (Roofline works rubbish removal, not yet incurred) — not counted above; if incurred the pool would be £140 over.
A25: Roofline works (new, 4 Sep estimate) | B25: 2100 | C25: 1990.4 | D25: -109.6 | E25: Quote £2,140 (4 Sep) unchanged = £2,100 here + £40 rubbish removal in the pooled fund (not yet incurred). Started 29 Sep, all roofline works completed Fri 16 Oct, including the lead flashing. The £150 scaffold tower was not needed (Luke used his ladder) — that benefit offsets the £40.40 of additional materials (£390.40 cash vs £350 allowance), net £109.60 under. ACTUAL £1,990.40 = £1,600 labour (INV-0291, paid 3 Oct by bank transfer) + £390.40 materials (paid in cash). Additional lead work (~£200) sits in Contingency.
A26: Contingency | B26: 5000 | C26: 16659.97 | D26: 11659.97 | E26: £16,659.97 drawn and PAID against the £5,000 pot, which is £11,659.97 over. Main driver: the £5,322.74 V4 materials order for the extended deck / shed area (named purpose #24, paid by phone 29 Sep), larger than the whole pot on its own. Travis Perkins settled 5 Oct; LG INV-0293 paid 9 Oct; Toolstation tools repaid 13 Oct; LG INV-0294 (£1,350 — driveway channel £350, extra decking labour £1,000) paid 17 Oct; pipe lagging (£177.58) paid 20 Oct; V4 QUO-0040 (£1,268) paid 22 Oct. The £1,200 whole-house soft wash was paid in cash on 19 Oct. Still to come: electrics, the new shed and three new grates, with no estimates yet. See the Contingency explained tab. Flagged, not hidden — same treatment as the Rubbish removal overage.
A27: TOTAL (as spent/committed to date) | B27: 69618.99 | C27: 71870.05 | D27: 2251.06
A29: Reconciliation check
A30: Summary's PROJECT TOTAL uses each cost centre's committed/ceiling figure — for Chimney, Coping, and Decking that's the real actual; for Materials, Rubbish, and Contingency (all pooled/reserve buckets) it's the provisional cap, not what's been spent so far. Recomputed on that same basis below to confirm nothing here is missing or double-counted against Summary.
A32: Chimney (actual) | C32: 4700
A33: Coping (actual) | C33: 5310
A34: Decking labour (actual) | C34: 17600
A35: Decking materials (actual) | C35: 32228.99
A36: Materials pooled (at £1,130 cap, per Summary) | C36: 1130
A37: Rubbish removal pooled (at £1,360 cap, per Summary) | C37: 1360
A38: Contingency (at £5,000 cap, per Summary) | C38: 5000
A39: Roofline works (actual, per estimate) | C39: 2100
A40: Recomputed total (Summary basis) | C40: =SUM(C32:C39) -> 69428.99
A41: Summary PROJECT TOTAL (committed) | C41: =Summary!C15 -> 69428.99
A42: Difference — should be £0.00 | C42: =C40-C41 -> 0

Sheet Contingency Explained
A1: Contingency explained — why the £5,000 pot has been exceeded
A2: As at 22 Oct 2026. Amounts inc VAT. Pulls live from the Contingency Drawdown, Summary and Cost Lines tabs. Scope tags on Travis Perkins invoices are inferred from invoice dates (confirm with Luke).
A3: ="Short answer: Contingency has £"&TEXT(B7,"#,##0.00")&" drawn against a £"&TEXT(B6,"#,##0")&" pot — £"&TEXT(B10,"#,##0.00")&" over. About "&TEXT(C14,"0%")&" of it is a new area of decking (the extended deck and shed base) that was not in the pot's original purposes." -> Short answer: Contingency has £16,659.97 drawn against a £5,000 pot — £11,659.97 over. About 62% of it is a new area of decking (the extended deck and shed base) that was not in the pot's original purposes.
A5: 1. The headline
A6: Pot agreed 1 Jul | B6: =Summary!C7 -> 5000 | E6: Agreed for: fence move/repair labour, soakaway fix before decking (cancelled 1 Sep, nothing drawn), drainage by the garage (nothing drawn), additional curved-decking labour, cement and bricks.
A7: Drawn (invoiced) | B7: =Summary!D7 -> 16659.97 | E7: Every Contingency invoice in the Invoice Register, paid or not.
A8: of which paid | B8: =Summary!E7 -> 16659.97
A9: of which invoiced, not yet paid | B9: =B7-B8 -> 0 | E9: Nothing outstanding in the Register: the Travis Perkins invoices were settled on 5 Oct, LG INV-0293 was paid on 9 Oct and LG INV-0294 was paid on 17 Oct and the pipe lagging on 20 Oct V4 QUO-0040 on 22 Oct and the soft wash (cash) on 19 Oct.
A10: OVER THE POT BY | B10: =B7-B6 -> 11659.97
A12: 2. Where the money went
A13: Driver | B13: £ | C13: Share | D13: On the 1 Jul list? | E13: What is in it
A14: Extended deck & shed base | B14: =SUMIFS('Contingency Drawdown'!$E$8:$E$60,'Contingency Drawdown'!$J$8:$J$60,"Extended deck & shed base") -> 10371.8 | C14: =B14/B$21 -> 0.62255814 | D14: No — arose later | E14: The new decking area the fence move opened up, plus the shed base: V4 materials order, extra digging, extra frame and the first Travis Perkins blocks and cement for it. Also the £1,050 additional deck labour on LG INV-0293. Includes the £1,000 extra decking labour on LG INV-0294 (17 Oct). Includes the £1,268 V4 QUO-0040 order (22 Oct).
A15: Main deck materials | B15: =SUMIFS('Contingency Drawdown'!$E$8:$E$60,'Contingency Drawdown'!$J$8:$J$60,"Main deck") -> 2760.44 | C15: =B15/B$21 -> 0.16569298 | D15: Partly — 'cement and bricks' | E15: Travis Perkins bulk materials for the original decking (cement, ballast, sand, blocks, ply, small tools) plus V4 subframe screw top-ups. Luke's quote has materials paid directly, so they had to land somewhere. Also the £800 curved-deck labour on LG INV-0293.
A16: Groundworks hire | B16: =SUMIFS('Contingency Drawdown'!$E$8:$E$60,'Contingency Drawdown'!$J$8:$J$60,"Groundworks (digger & dumper)") -> 836.37 | C16: =B16/B$21 -> 0.050202371 | D16: No | E16: Digger, dumper and clean-up. Used for both the main deck widening and the new shed area, so not split between them.
A17: Fence relocation | B17: =SUMIFS('Contingency Drawdown'!$E$8:$E$60,'Contingency Drawdown'!$J$8:$J$60,"Fence relocation") -> 606.17 | C17: =B17/B$21 -> 0.036384819 | D17: Yes — fence move | E17: Fence move labour (chimney side, boundary reclaim) and the fence materials.
A18: Chimney & coping extras, shared items | B18: =SUMIFS('Contingency Drawdown'!$E$8:$E$60,'Contingency Drawdown'!$J$8:$J$60,"Chimney & coping")+SUMIFS('Contingency Drawdown'!$E$8:$E$60,'Contingency Drawdown'!$J$8:$J$60,"Shared / site-wide") -> 1735.19 | C18: =B18/B$21 -> 0.10415325 | D18: No | E18: Coping condensation-prep, chimney cowl upgrade, and one shared small-consumables invoice. Also the pipe lagging for the outside tap/pipework (£177.58, 20 Oct). Also the whole-house soft wash (£1,200 cash, 19 Oct).
A19: Driveway channel | B19: =SUMIFS('Contingency Drawdown'!$E$8:$E$60,'Contingency Drawdown'!$J$8:$J$60,"Driveway channel") -> 350 | C19: =B19/B$21 -> 0.021008441 | D19: No — arose later | E19: Water-softener waste channel (rainy-day task, Gantt 3.1), done in half a day on 14 Oct by Luke and Max, £350 on LG INV-0294.
A20: New shed & electrics | B20: =SUMIFS('Contingency Drawdown'!$E$8:$E$60,'Contingency Drawdown'!$J$8:$J$60,"New shed & electrics") -> 0 | C20: =B20/B$21 -> 0 | D20: No — arose later | E20: Workstream 8: the new shed, its installation and the electrics (first fix done 22 Oct; call-out charge not yet invoiced). Nothing drawn yet; costs to come, no estimates.
A21: TOTAL DRAWN | B21: =SUM(B14:B20) -> 16659.97 | C21: =SUM(C14:C20) -> 1
A22: Check: total less Summary 'Invoiced' (must be 0.00) | B22: =ROUND(B21-Summary!D7,2) -> 0
A24: 3. Inside the drivers
A25: Line | B25: £ | D25: Purpose # | E25: Source
A26: V4 order — shed area / extended deck materials | B26: =SUMIFS('Contingency Drawdown'!$E$8:$E$60,'Contingency Drawdown'!$A$8:$A$60,24) -> 5322.74 | D26: #24 | E26: Placed and paid by phone 29 Sep (quote QUO-0031).
A27: Extra digging — wider gate area + shed/additional deck | B27: =SUMIFS('Contingency Drawdown'!$E$8:$E$60,'Contingency Drawdown'!$A$8:$A$60,11) -> 1260 | D27: #11 | E27: Invoiced and paid 11 Sep.
A28: Extra frame — wider deck gate area | B28: =SUMIFS('Contingency Drawdown'!$E$8:$E$60,'Contingency Drawdown'!$A$8:$A$60,14) -> 360 | D28: #14 | E28: Invoiced and paid 11 Sep.
A29: Travis Perkins blocks and cement dated 21 Sep | B29: =SUMIFS('Contingency Drawdown'!$E$8:$E$60,'Contingency Drawdown'!$A$8:$A$60,29)+SUMIFS('Contingency Drawdown'!$E$8:$E$60,'Contingency Drawdown'!$A$8:$A$60,30) -> 111.06 | D29: #29, #30 | E29: Two invoices, paid 5 Oct.
A30: Extra deck labour — additional deck (LG INV-0293) | B30: =SUMIFS('Contingency Drawdown'!$E$8:$E$60,'Contingency Drawdown'!$A$8:$A$60,32) -> 1050 | D30: #32 | E30: Invoiced and paid 9 Oct (£1,050, bank transfer).
A31: Extra decking labour (LG INV-0294) | B31: =SUMIFS('Contingency Drawdown'!$E$8:$E$60,'Contingency Drawdown'!$A$8:$A$60,36) -> 1000 | D31: #36 | E31: Invoiced and paid 17 Oct (£1,000, bank transfer).
A32: V4 order — materials to complete the substructure (QUO-0040) | B32: =SUMIFS('Contingency Drawdown'!$E$8:$E$60,'Contingency Drawdown'!$A$8:$A$60,38) -> 1268 | D32: #38 | E32: Delivered Mon 19 Oct; paid by card 22 Oct (£1,268). Some Plas-Pro may be used on the main decking.
A33: Extended deck & shed base — subtotal | B33: =SUM(B26:B32) -> 10371.8
A34: Check against section 2 (must be 0.00) | B34: =ROUND(B33-B14,2) -> 0
A35: Travis Perkins bulk materials, main deck | B35: =B15-B36-B37-B38 -> 1592.15 | D35: #16–#22, #25–#27 | E35: Invoices dated before 21 Sep.
A36: V4 subframe screw top-ups | B36: =SUMIFS('Contingency Drawdown'!$E$8:$E$60,'Contingency Drawdown'!$A$8:$A$60,8)+SUMIFS('Contingency Drawdown'!$E$8:$E$60,'Contingency Drawdown'!$A$8:$A$60,9) -> 283.32 | D36: #8, #9 | E36: Two top-ups of 15 boxes.
A37: Curved-decking labour (LG INV-0293) | B37: =SUMIFS('Contingency Drawdown'!$E$8:$E$60,'Contingency Drawdown'!$A$8:$A$60,4) -> 800 | D37: #4 | E37: Invoiced and paid 9 Oct (£800 of the £1,000 agreed 24 Sep).
A38: Saw blades and drill bits (Toolstation) | B38: =SUMIFS('Contingency Drawdown'!$E$8:$E$60,'Contingency Drawdown'!$A$8:$A$60,33) -> 84.97 | D38: #33 | E38: Bought by Luke on his card 6 Oct; repaid in cash 13 Oct. Tagged Main deck, used throughout.
A39: Digger hire | B39: =SUMIFS('Contingency Drawdown'!$E$8:$E$60,'Contingency Drawdown'!$A$8:$A$60,10) -> 378.58 | D39: #10 | E39: 3–8 Sep, on Luke's TP account.
A40: Dumper hire | B40: =SUMIFS('Contingency Drawdown'!$E$8:$E$60,'Contingency Drawdown'!$A$8:$A$60,28) -> 277.79 | D40: #28 | E40: 2–8 Sep, on Luke's TP account.
A41: Clean-up + small tree dig | B41: =SUMIFS('Contingency Drawdown'!$E$8:$E$60,'Contingency Drawdown'!$A$8:$A$60,12) -> 180 | D41: #12 | E41: Invoiced and paid 11 Sep.
A42: Fence move labour | B42: =SUMIFS('Contingency Drawdown'!$E$8:$E$60,'Contingency Drawdown'!$A$8:$A$60,13) -> 315 | D42: #13 | E42: Chimney side / side (a) boundary. Paid 11 Sep.
A43: Fence materials | B43: =SUMIFS('Contingency Drawdown'!$E$8:$E$60,'Contingency Drawdown'!$A$8:$A$60,23) -> 291.17 | D43: #23 | E43: Travis Perkins invoice 1051142985.
...

Sheet Contingency Drawdown
A1: Contingency Drawdown — £5,000 pot (agreed Lara/Luke, 1 Jul 2026)
A2: One row per named purpose (#1–#38), sorted by purpose number. Drawn and Paid come from the Invoice Register (matched on its 'Named purpose #' column); Pending comes from Cost Lines. Sort or filter freely: 'pot remaining' is worked out from the invoice dates, so it stays correct in any order. Travis Perkins invoices were settled on 5 Oct (net £2,169.04 after Luke's 6 Oct repayment — see TP Account).
A4: Opening pot: | B4: 5000 | C4: Remaining: | D4: =B4-SUM($E$8:$E$60) -> -11659.97
A5: Drawn: | B5: =SUM($E$8:$E$60) -> 16659.97 | C5: Paid: | D5: =SUM($F$8:$F$60) -> 16659.97 | E5: Pending: | F5: =SUM($H$8:$H$60) -> 247.22
C6: Check vs Register (must be 0.00): | D6: =ROUND(SUM($E$8:$E$60)-SUMIF('Invoice Register'!$B:$B,"Contingency",'Invoice Register'!$F:$F),2) -> 0
A7: Named purpose # | B7: Invoice date | C7: Purpose | D7: Supplier / detail | E7: Drawn £ | F7: Paid £ | G7: Unpaid £ | H7: Pending (not yet drawn) £ | I7: Status | J7: Scope | K7: Pot remaining at this invoice date £ | L7: Notes
A8: 1 | C8: Fence move / repair labour | D8: Luke (LG Building and Roofing) | E8: =IF($A8="","",SUMIFS('Invoice Register'!$F:$F,'Invoice Register'!$B:$B,"Contingency",'Invoice Register'!$L:$L,$A8)) -> 0 | F8: =IF($A8="","",SUMIFS('Invoice Register'!$F:$F,'Invoice Register'!$B:$B,"Contingency",'Invoice Register'!$L:$L,$A8,'Invoice Register'!$G:$G,"<>")) -> 0 | G8: =IF($A8="","",E8-F8) -> 0 | H8: =IF($A8="","",IF(E8>0,0,SUMIF('Cost Lines'!$C:$C,"*purpose #"&$A8&" *",'Cost Lines'!$F:$F))) -> 0 | I8: Superseded by #13 | J8: Fence relocation | K8: =IF(OR($A8="",$B8=""),"",$B$4-SUMIFS($E$8:$E$60,$B$8:$B$60,"<="&$B8)) | L8: On the 1 Jul list. Superseded by #13 (fence move, chimney side).
A9: 2 | C9: Soakaway fix before decking | D9: — | E9: =IF($A9="","",SUMIFS('Invoice Register'!$F:$F,'Invoice Register'!$B:$B,"Contingency",'Invoice Register'!$L:$L,$A9)) -> 0 | F9: =IF($A9="","",SUMIFS('Invoice Register'!$F:$F,'Invoice Register'!$B:$B,"Contingency",'Invoice Register'!$L:$L,$A9,'Invoice Register'!$G:$G,"<>")) -> 0 | G9: =IF($A9="","",E9-F9) -> 0 | H9: =IF($A9="","",IF(E9>0,0,SUMIF('Cost Lines'!$C:$C,"*purpose #"&$A9&" *",'Cost Lines'!$F:$F))) -> 0 | I9: Cancelled 1 Sep | K9: =IF(OR($A9="",$B9=""),"",$B$4-SUMIFS($E$8:$E$60,$B$8:$B$60,"<="&$B9)) | L9: On the 1 Jul list. CANCELLED 1 Sep — cost-benefit not worth it. Nothing drawn.
A10: 3 | C10: Drainage by the garage | D10: — | E10: =IF($A10="","",SUMIFS('Invoice Register'!$F:$F,'Invoice Register'!$B:$B,"Contingency",'Invoice Register'!$L:$L,$A10)) -> 0 | F10: =IF($A10="","",SUMIFS('Invoice Register'!$F:$F,'Invoice Register'!$B:$B,"Contingency",'Invoice Register'!$L:$L,$A10,'Invoice Register'!$G:$G,"<>")) -> 0 | G10: =IF($A10="","",E10-F10) -> 0 | H10: =IF($A10="","",IF(E10>0,0,SUMIF('Cost Lines'!$C:$C,"*purpose #"&$A10&" *",'Cost Lines'!$F:$F))) -> 0 | I10: Nothing drawn | K10: =IF(OR($A10="",$B10=""),"",$B$4-SUMIFS($E$8:$E$60,$B$8:$B$60,"<="&$B10)) | L10: On the 1 Jul list. Nothing drawn.
A11: 4 | B11: 46304 | C11: Additional curved-decking labour | D11: Luke (LG Building and Roofing) | E11: =IF($A11="","",SUMIFS('Invoice Register'!$F:$F,'Invoice Register'!$B:$B,"Contingency",'Invoice Register'!$L:$L,$A11)) -> 800 | F11: =IF($A11="","",SUMIFS('Invoice Register'!$F:$F,'Invoice Register'!$B:$B,"Contingency",'Invoice Register'!$L:$L,$A11,'Invoice Register'!$G:$G,"<>")) -> 800 | G11: =IF($A11="","",E11-F11) -> 0 | H11: =IF($A11="","",IF(E11>0,0,SUMIF('Cost Lines'!$C:$C,"*purpose #"&$A11&" *",'Cost Lines'!$F:$F))) -> 0 | I11: =IF(E11>0,IF(F11>=E11-0.005,"Paid",IF(F11>0,"Part paid","Invoiced, unpaid")),IF(H11>0,"Not yet invoiced","")) -> Paid | J11: Main deck | K11: =IF(OR($A11="",$B11=""),"",$B$4-SUMIFS($E$8:$E$60,$B$8:$B$60,"<="&$B11)) -> -7664.39 | L11: On the 1 Jul list. AGREED 24 Sep at £1,000 full price / £900 cash. INVOICED 9 Oct: £800 on INV-0293 (the curves), paid the same day by bank transfer — Luke billed £800, not the £1,000 agreed. The other £200 is not expected unless Luke bills it.
A12: 5 | C12: Cement & bricks | D12: — | E12: =IF($A12="","",SUMIFS('Invoice Register'!$F:$F,'Invoice Register'!$B:$B,"Contingency",'Invoice Register'!$L:$L,$A12)) -> 0 | F12: =IF($A12="","",SUMIFS('Invoice Register'!$F:$F,'Invoice Register'!$B:$B,"Contingency",'Invoice Register'!$L:$L,$A12,'Invoice Register'!$G:$G,"<>")) -> 0 | G12: =IF($A12="","",E12-F12) -> 0 | H12: =IF($A12="","",IF(E12>0,0,SUMIF('Cost Lines'!$C:$C,"*purpose #"&$A12&" *",'Cost Lines'!$F:$F))) -> 0 | I12: Covered by #16–#30 | K12: =IF(OR($A12="",$B12=""),"",$B$4-SUMIFS($E$8:$E$60,$B$8:$B$60,"<="&$B12)) | L12: On the 1 Jul list. Actual draws are recorded under the specific Travis Perkins purposes #16–#30.
A13: 6 | B13: 46247 | C13: Coping condensation-prep (labour + DPC roll) | D13: LG Building and Roofing Ltd — INV-0288; LG Building and Roofing Ltd (Travis Perkins account) — TP invoice 1048887075 | E13: =IF($A13="","",SUMIFS('Invoice Register'!$F:$F,'Invoice Register'!$B:$B,"Contingency",'Invoice Register'!$L:$L,$A13)) -> 276.42 | F13: =IF($A13="","",SUMIFS('Invoice Register'!$F:$F,'Invoice Register'!$B:$B,"Contingency",'Invoice Register'!$L:$L,$A13,'Invoice Register'!$G:$G,"<>")) -> 276.42 | G13: =IF($A13="","",E13-F13) -> 0 | H13: =IF($A13="","",IF(E13>0,0,SUMIF('Cost Lines'!$C:$C,"*purpose #"&$A13&" *",'Cost Lines'!$F:$F))) -> 0 | I13: =IF(E13>0,IF(F13>=E13-0.005,"Paid",IF(F13>0,"Part paid","Invoiced, unpaid")),IF(H13>0,"Not yet invoiced","")) -> Paid | J13: Chimney & coping | K13: =IF(OR($A13="",$B13=""),"",$B$4-SUMIFS($E$8:$E$60,$B$8:$B$60,"<="&$B13)) -> 4552.54 | L13: Labour £250 (INV-0288, 14 Aug) + Damplas DPC roll £26.42 (17 Aug).
A14: 7 | B14: 46244 | C14: Chimney cowl upgrade — stainless steel | D14: StoveWorldUK — Order #147399 | E14: =IF($A14="","",SUMIFS('Invoice Register'!$F:$F,'Invoice Register'!$B:$B,"Contingency",'Invoice Register'!$L:$L,$A14)) -> 62.9 | F14: =IF($A14="","",SUMIFS('Invoice Register'!$F:$F,'Invoice Register'!$B:$B,"Contingency",'Invoice Register'!$L:$L,$A14,'Invoice Register'!$G:$G,"<>")) -> 62.9 | G14: =IF($A14="","",E14-F14) -> 0 | H14: =IF($A14="","",IF(E14>0,0,SUMIF('Cost Lines'!$C:$C,"*purpose #"&$A14&" *",'Cost Lines'!$F:$F))) -> 0 | I14: =IF(E14>0,IF(F14>=E14-0.005,"Paid",IF(F14>0,"Part paid","Invoiced, unpaid")),IF(H14>0,"Not yet invoiced","")) -> Paid | J14: Chimney & coping | K14: =IF(OR($A14="",$B14=""),"",$B$4-SUMIFS($E$8:$E$60,$B$8:$B$60,"<="&$B14)) -> 4937.1
A15: 8 | B15: 46258 | C15: V4 subframe screw top-up | D15: V4 Wood Flooring Ltd — V4FQ-17702 | E15: =IF($A15="","",SUMIFS('Invoice Register'!$F:$F,'Invoice Register'!$B:$B,"Contingency",'Invoice Register'!$L:$L,$A15)) -> 141.66 | F15: =IF($A15="","",SUMIFS('Invoice Register'!$F:$F,'Invoice Register'!$B:$B,"Contingency",'Invoice Register'!$L:$L,$A15,'Invoice Register'!$G:$G,"<>")) -> 141.66 | G15: =IF($A15="","",E15-F15) -> 0 | H15: =IF($A15="","",IF(E15>0,0,SUMIF('Cost Lines'!$C:$C,"*purpose #"&$A15&" *",'Cost Lines'!$F:$F))) -> 0 | I15: =IF(E15>0,IF(F15>=E15-0.005,"Paid",IF(F15>0,"Part paid","Invoiced, unpaid")),IF(H15>0,"Not yet invoiced","")) -> Paid | J15: Main deck | K15: =IF(OR($A15="",$B15=""),"",$B$4-SUMIFS($E$8:$E$60,$B$8:$B$60,"<="&$B15)) -> 3359.68 | L15: 15 boxes of structural subframe screws.
A16: 9 | B16: 46275 | C16: V4 subframe screw top-up #2 | D16: V4 Wood Flooring Ltd — TBC | E16: =IF($A16="","",SUMIFS('Invoice Register'!$F:$F,'Invoice Register'!$B:$B,"Contingency",'Invoice Register'!$L:$L,$A16)) -> 141.66 | F16: =IF($A16="","",SUMIFS('Invoice Register'!$F:$F,'Invoice Register'!$B:$B,"Contingency",'Invoice Register'!$L:$L,$A16,'Invoice Register'!$G:$G,"<>")) -> 141.66 | G16: =IF($A16="","",E16-F16) -> 0 | H16: =IF($A16="","",IF(E16>0,0,SUMIF('Cost Lines'!$C:$C,"*purpose #"&$A16&" *",'Cost Lines'!$F:$F))) -> 0 | I16: =IF(E16>0,IF(F16>=E16-0.005,"Paid",IF(F16>0,"Part paid","Invoiced, unpaid")),IF(H16>0,"Not yet invoiced","")) -> Paid | J16: Main deck | K16: =IF(OR($A16="",$B16=""),"",$B$4-SUMIFS($E$8:$E$60,$B$8:$B$60,"<="&$B16)) -> 2406.63 | L16: 15 boxes of structural subframe screws. Paid 10 Sep.
A17: 10 | B17: 46274 | C17: Digger hire | D17: Travis Perkins Hire (Luke's account) — 1051011143 | E17: =IF($A17="","",SUMIFS('Invoice Register'!$F:$F,'Invoice Register'!$B:$B,"Contingency",'Invoice Register'!$L:$L,$A17)) -> 378.58 | F17: =IF($A17="","",SUMIFS('Invoice Register'!$F:$F,'Invoice Register'!$B:$B,"Contingency",'Invoice Register'!$L:$L,$A17,'Invoice Register'!$G:$G,"<>")) -> 378.58 | G17: =IF($A17="","",E17-F17) -> 0 | H17: =IF($A17="","",IF(E17>0,0,SUMIF('Cost Lines'!$C:$C,"*purpose #"&$A17&" *",'Cost Lines'!$F:$F))) -> 0 | I17: =IF(E17>0,IF(F17>=E17-0.005,"Paid",IF(F17>0,"Part paid","Invoiced, unpaid")),IF(H17>0,"Not yet invoiced","")) -> Paid | J17: Groundworks (digger & dumper) | K17: =IF(OR($A17="",$B17=""),"",$B$4-SUMIFS($E$8:$E$60,$B$8:$B$60,"<="&$B17)) -> 2673.02 | L17: 3–8 Sep, Travis Perkins Hire. Actual invoice £378.58 replaced the £530 estimate; no barrow loader charge appears on the invoice (flagged, not assumed).
A18: 11 | B18: 46276 | C18: Extra digging — wider gate area + shed/additional deck | D18: LG Building and Roofing Ltd (cash) | E18: =IF($A18="","",SUMIFS('Invoice Register'!$F:$F,'Invoice Register'!$B:$B,"Contingency",'Invoice Register'!$L:$L,$A18)) -> 1260 | F18: =IF($A18="","",SUMIFS('Invoice Register'!$F:$F,'Invoice Register'!$B:$B,"Contingency",'Invoice Register'!$L:$L,$A18,'Invoice Register'!$G:$G,"<>")) -> 1260 | G18: =IF($A18="","",E18-F18) -> 0 | H18: =IF($A18="","",IF(E18>0,0,SUMIF('Cost Lines'!$C:$C,"*purpose #"&$A18&" *",'Cost Lines'!$F:$F))) -> 0 | I18: =IF(E18>0,IF(F18>=E18-0.005,"Paid",IF(F18>0,"Part paid","Invoiced, unpaid")),IF(H18>0,"Not yet invoiced","")) -> Paid | J18: Extended deck & shed base | K18: =IF(OR($A18="",$B18=""),"",$B$4-SUMIFS($E$8:$E$60,$B$8:$B$60,"<="&$B18)) -> -17.83 | L18: Part of Luke's 11 Sep extras invoice (£2,350 quoted, £2,115 paid after the 10% cash discount).
A19: 12 | B19: 46276 | C19: Clean-up + small tree dig | D19: LG Building and Roofing Ltd (cash) | E19: =IF($A19="","",SUMIFS('Invoice Register'!$F:$F,'Invoice Register'!$B:$B,"Contingency",'Invoice Register'!$L:$L,$A19)) -> 180 | F19: =IF($A19="","",SUMIFS('Invoice Register'!$F:$F,'Invoice Register'!$B:$B,"Contingency",'Invoice Register'!$L:$L,$A19,'Invoice Register'!$G:$G,"<>")) -> 180 | G19: =IF($A19="","",E19-F19) -> 0 | H19: =IF($A19="","",IF(E19>0,0,SUMIF('Cost Lines'!$C:$C,"*purpose #"&$A19&" *",'Cost Lines'!$F:$F))) -> 0 | I19: =IF(E19>0,IF(F19>=E19-0.005,"Paid",IF(F19>0,"Part paid","Invoiced, unpaid")),IF(H19>0,"Not yet invoiced","")) -> Paid | J19: Groundworks (digger & dumper) | K19: =IF(OR($A19="",$B19=""),"",$B$4-SUMIFS($E$8:$E$60,$B$8:$B$60,"<="&$B19)) -> -17.83 | L19: Part of Luke's 11 Sep extras invoice.
A20: 13 | B20: 46276 | C20: Fence move — chimney side / side (a) boundary reclaim | D20: LG Building and Roofing Ltd (cash) | E20: =IF($A20="","",SUMIFS('Invoice Register'!$F:$F,'Invoice Register'!$B:$B,"Contingency",'Invoice Register'!$L:$L,$A20)) -> 315 | F20: =IF($A20="","",SUMIFS('Invoice Register'!$F:$F,'Invoice Register'!$B:$B,"Contingency",'Invoice Register'!$L:$L,$A20,'Invoice Register'!$G:$G,"<>")) -> 315 | G20: =IF($A20="","",E20-F20) -> 0 | H20: =IF($A20="","",IF(E20>0,0,SUMIF('Cost Lines'!$C:$C,"*purpose #"&$A20&" *",'Cost Lines'!$F:$F))) -> 0 | I20: =IF(E20>0,IF(F20>=E20-0.005,"Paid",IF(F20>0,"Part paid","Invoiced, unpaid")),IF(H20>0,"Not yet invoiced","")) -> Paid | J20: Fence relocation | K20: =IF(OR($A20="",$B20=""),"",$B$4-SUMIFS($E$8:$E$60,$B$8:$B$60,"<="&$B20)) -> -17.83 | L20: Part of Luke's 11 Sep extras invoice. Supersedes #1.
A21: 14 | B21: 46276 | C21: Extra frame — wider deck gate area | D21: LG Building and Roofing Ltd (cash) | E21: =IF($A21="","",SUMIFS('Invoice Register'!$F:$F,'Invoice Register'!$B:$B,"Contingency",'Invoice Register'!$L:$L,$A21)) -> 360 | F21: =IF($A21="","",SUMIFS('Invoice Register'!$F:$F,'Invoice Register'!$B:$B,"Contingency",'Invoice Register'!$L:$L,$A21,'Invoice Register'!$G:$G,"<>")) -> 360 | G21: =IF($A21="","",E21-F21) -> 0 | H21: =IF($A21="","",IF(E21>0,0,SUMIF('Cost Lines'!$C:$C,"*purpose #"&$A21&" *",'Cost Lines'!$F:$F))) -> 0 | I21: =IF(E21>0,IF(F21>=E21-0.005,"Paid",IF(F21>0,"Part paid","Invoiced, unpaid")),IF(H21>0,"Not yet invoiced","")) -> Paid | J21: Extended deck & shed base | K21: =IF(OR($A21="",$B21=""),"",$B$4-SUMIFS($E$8:$E$60,$B$8:$B$60,"<="&$B21)) -> -17.83 | L21: Part of Luke's 11 Sep extras invoice.
A22: 15 | C22: V4 subframe screw top-up #3 | D22: V4 Wood Flooring Ltd | E22: =IF($A22="","",SUMIFS('Invoice Register'!$F:$F,'Invoice Register'!$B:$B,"Contingency",'Invoice Register'!$L:$L,$A22)) -> 0 | F22: =IF($A22="","",SUMIFS('Invoice Register'!$F:$F,'Invoice Register'!$B:$B,"Contingency",'Invoice Register'!$L:$L,$A22,'Invoice Register'!$G:$G,"<>")) -> 0 | G22: =IF($A22="","",E22-F22) -> 0 | H22: =IF($A22="","",IF(E22>0,0,SUMIF('Cost Lines'!$C:$C,"*purpose #"&$A22&" *",'Cost Lines'!$F:$F))) -> 47.22 | I22: Invoiced, unpaid (£47.22) | J22: Main deck | K22: =IF(OR($A22="",$B22=""),"",$B$4-SUMIFS($E$8:$E$60,$B$8:$B$60,"<="&$B22)) | L22: V4 invoice #336484, £47.22, due 12 Oct, 'additional screws' — received but STILL UNPAID (17 Oct). Replaces the earlier £141.66 / 15-box estimate. Logged in Cost Lines only until paid.
A23: 16 | B23: 46252 | C23: TP materials — cement, blade | D23: Travis Perkins (Luke's account) — 1049651867 | E23: =IF($A23="","",SUMIFS('Invoice Register'!$F:$F,'Invoice Register'!$B:$B,"Contingency",'Invoice Register'!$L:$L,$A23)) -> 144.58 | F23: =IF($A23="","",SUMIFS('Invoice Register'!$F:$F,'Invoice Register'!$B:$B,"Contingency",'Invoice Register'!$L:$L,$A23,'Invoice Register'!$G:$G,"<>")) -> 144.58 | G23: =IF($A23="","",E23-F23) -> 0 | H23: =IF($A23="","",IF(E23>0,0,SUMIF('Cost Lines'!$C:$C,"*purpose #"&$A23&" *",'Cost Lines'!$F:$F))) -> 0 | I23: =IF(E23>0,IF(F23>=E23-0.005,"Paid",IF(F23>0,"Part paid","Invoiced, unpaid")),IF(H23>0,"Not yet invoiced","")) -> Paid | J23: Main deck | K23: =IF(OR($A23="",$B23=""),"",$B$4-SUMIFS($E$8:$E$60,$B$8:$B$60,"<="&$B23)) -> 4060.84 | L23: Travis Perkins invoice 1049651867.
A24: 17 | B24: 46253 | C24: TP materials — plywood, drill bit, screws, gloves | D24: Travis Perkins (Luke's account) — 1049757851 | E24: =IF($A24="","",SUMIFS('Invoice Register'!$F:$F,'Invoice Register'!$B:$B,"Contingency",'Invoice Register'!$L:$L,$A24)) -> 74.34 | F24: =IF($A24="","",SUMIFS('Invoice Register'!$F:$F,'Invoice Register'!$B:$B,"Contingency",'Invoice Register'!$L:$L,$A24,'Invoice Register'!$G:$G,"<>")) -> 74.34 | G24: =IF($A24="","",E24-F24) -> 0 | H24: =IF($A24="","",IF(E24>0,0,SUMIF('Cost Lines'!$C:$C,"*purpose #"&$A24&" *",'Cost Lines'!$F:$F))) -> 0 | I24: =IF(E24>0,IF(F24>=E24-0.005,"Paid",IF(F24>0,"Part paid","Invoiced, unpaid")),IF(H24>0,"Not yet invoiced","")) -> Paid | J24: Main deck | K24: =IF(OR($A24="",$B24=""),"",$B$4-SUMIFS($E$8:$E$60,$B$8:$B$60,"<="&$B24)) -> 3986.5 | L24: Travis Perkins invoice 1049757851.
A25: 18 | B25: 46254 | C25: TP materials — ballast, cement, blocks, pallet deposit | D25: Travis Perkins (Luke's account) — 1049844268 | E25: =IF($A25="","",SUMIFS('Invoice Register'!$F:$F,'Invoice Register'!$B:$B,"Contingency",'Invoice Register'!$L:$L,$A25)) -> 462.5 | F25: =IF($A25="","",SUMIFS('Invoice Register'!$F:$F,'Invoice Register'!$B:$B,"Contingency",'Invoice Register'!$L:$L,$A25,'Invoice Register'!$G:$G,"<>")) -> 462.5 | G25: =IF($A25="","",E25-F25) -> 0 | H25: =IF($A25="","",IF(E25>0,0,SUMIF('Cost Lines'!$C:$C,"*purpose #"&$A25&" *",'Cost Lines'!$F:$F))) -> 0 | I25: =IF(E25>0,IF(F25>=E25-0.005,"Paid",IF(F25>0,"Part paid","Invoiced, unpaid")),IF(H25>0,"Not yet invoiced","")) -> Paid | J25: Main deck | K25: =IF(OR($A25="",$B25=""),"",$B$4-SUMIFS($E$8:$E$60,$B$8:$B$60,"<="&$B25)) -> 3501.34 | L25: Travis Perkins invoice 1049844268. Includes a £30.30 REFUNDABLE pallet deposit (not a final cost).
A26: 19 | B26: 46254 | C26: TP materials — flat packers | D26: Travis Perkins (Luke's account) — 1049844267 | E26: =IF($A26="","",SUMIFS('Invoice Register'!$F:$F,'Invoice Register'!$B:$B,"Contingency",'Invoice Register'!$L:$L,$A26)) -> 22.66 | F26: =IF($A26="","",SUMIFS('Invoice Register'!$F:$F,'Invoice Register'!$B:$B,"Contingency",'Invoice Register'!$L:$L,$A26,'Invoice Register'!$G:$G,"<>")) -> 22.66 | G26: =IF($A26="","",E26-F26) -> 0 | H26: =IF($A26="","",IF(E26>0,0,SUMIF('Cost Lines'!$C:$C,"*purpose #"&$A26&" *",'Cost Lines'!$F:$F))) -> 0 | I26: =IF(E26>0,IF(F26>=E26-0.005,"Paid",IF(F26>0,"Part paid","Invoiced, unpaid")),IF(H26>0,"Not yet invoiced","")) -> Paid | J26: Main deck | K26: =IF(OR($A26="",$B26=""),"",$B$4-SUMIFS($E$8:$E$60,$B$8:$B$60,"<="&$B26)) -> 3501.34 | L26: Travis Perkins invoice 1049844267.
A27: 20 | B27: 46273 | C27: TP materials — plywood, line marker | D27: Travis Perkins (Luke's account) — 1050903283 | E27: =IF($A27="","",SUMIFS('Invoice Register'!$F:$F,'Invoice Register'!$B:$B,"Contingency",'Invoice Register'!$L:$L,$A27)) -> 58.62 | F27: =IF($A27="","",SUMIFS('Invoice Register'!$F:$F,'Invoice Register'!$B:$B,"Contingency",'Invoice Register'!$L:$L,$A27,'Invoice Register'!$G:$G,"<>")) -> 58.62 | G27: =IF($A27="","",E27-F27) -> 0 | H27: =IF($A27="","",IF(E27>0,0,SUMIF('Cost Lines'!$C:$C,"*purpose #"&$A27&" *",'Cost Lines'!$F:$F))) -> 0 | I27: =IF(E27>0,IF(F27>=E27-0.005,"Paid",IF(F27>0,"Part paid","Invoiced, unpaid")),IF(H27>0,"Not yet invoiced","")) -> Paid | J27: Main deck | K27: =IF(OR($A27="",$B27=""),"",$B$4-SUMIFS($E$8:$E$60,$B$8:$B$60,"<="&$B27)) -> 3051.6 | L27: Travis Perkins invoice 1050903283.
A28: 21 | B28: 46275 | C28: TP materials — ballast, cement | D28: Travis Perkins (Luke's account) — 1051072869 | E28: =IF($A28="","",SUMIFS('Invoice Register'!$F:$F,'Invoice Register'!$B:$B,"Contingency",'Invoice Register'!$L:$L,$A28)) -> 124.73 | F28: =IF($A28="","",SUMIFS('Invoice Register'!$F:$F,'Invoice Register'!$B:$B,"Contingency",'Invoice Register'!$L:$L,$A28,'Invoice Register'!$G:$G,"<>")) -> 124.73 | G28: =IF($A28="","",E28-F28) -> 0 | H28: =IF($A28="","",IF(E28>0,0,SUMIF('Cost Lines'!$C:$C,"*purpose #"&$A28&" *",'Cost Lines'!$F:$F))) -> 0 | I28: =IF(E28>0,IF(F28>=E28-0.005,"Paid",IF(F28>0,"Part paid","Invoiced, unpaid")),IF(H28>0,"Not yet invoiced","")) -> Paid | J28: Main deck | K28: =IF(OR($A28="",$B28=""),"",$B$4-SUMIFS($E$8:$E$60,$B$8:$B$60,"<="&$B28)) -> 2406.63 | L28: Travis Perkins invoice 1051072869.
A29: 22 | B29: 46276 | C29: TP materials — gloves, woodscrews | D29: Travis Perkins (Luke's account) — 1051162218 | E29: =IF($A29="","",SUMIFS('Invoice Register'!$F:$F,'Invoice Register'!$B:$B,"Contingency",'Invoice Register'!$L:$L,$A29)) -> 18.29 | F29: =IF($A29="","",SUMIFS('Invoice Register'!$F:$F,'Invoice Register'!$B:$B,"Contingency",'Invoice Register'!$L:$L,$A29,'Invoice Register'!$G:$G,"<>")) -> 18.29 | G29: =IF($A29="","",E29-F29) -> 0 | H29: =IF($A29="","",IF(E29>0,0,SUMIF('Cost Lines'!$C:$C,"*purpose #"&$A29&" *",'Cost Lines'!$F:$F))) -> 0 | I29: =IF(E29>0,IF(F29>=E29-0.005,"Paid",IF(F29>0,"Part paid","Invoiced, unpaid")),IF(H29>0,"Not yet invoiced","")) -> Paid | J29: Shared / site-wide | K29: =IF(OR($A29="",$B29=""),"",$B$4-SUMIFS($E$8:$E$60,$B$8:$B$60,"<="&$B29)) -> -17.83 | L29: Travis Perkins invoice 1051162218.
A30: 23 | B30: 46276 | C30: TP fence materials — posts, Postcrete, rail brackets, pegs, timber | D30: Travis Perkins (Luke's account) — 1051142985 | E30: =IF($A30="","",SUMIFS('Invoice Register'!$F:$F,'Invoice Register'!$B:$B,"Contingency",'Invoice Register'!$L:$L,$A30)) -> 291.17 | F30: =IF($A30="","",SUMIFS('Invoice Register'!$F:$F,'Invoice Register'!$B:$B,"Contingency",'Invoice Register'!$L:$L,$A30,'Invoice Register'!$G:$G,"<>")) -> 291.17 | G30: =IF($A30="","",E30-F30) -> 0 | H30: =IF($A30="","",IF(E30>0,0,SUMIF('Cost Lines'!$C:$C,"*purpose #"&$A30&" *",'Cost Lines'!$F:$F))) -> 0 | I30: =IF(E30>0,IF(F30>=E30-0.005,"Paid",IF(F30>0,"Part paid","Invoiced, unpaid")),IF(H30>0,"Not yet invoiced","")) -> Paid | J30: Fence relocation | K30: =IF(OR($A30="",$B30=""),"",$B$4-SUMIFS($E$8:$E$60,$B$8:$B$60,"<="&$B30)) -> -17.83 | L30: Travis Perkins invoice 1051142985.
A31: 24 | B31: 46294 | C31: V4 materials — shed area / extended deck | D31: V4 Wood Flooring Ltd — QUO-0031 | E31: =IF($A31="","",SUMIFS('Invoice Register'!$F:$F,'Invoice Register'!$B:$B,"Contingency",'Invoice Register'!$L:$L,$A31)) -> 5322.74 | F31: =IF($A31="","",SUMIFS('Invoice Register'!$F:$F,'Invoice Register'!$B:$B,"Contingency",'Invoice Register'!$L:$L,$A31,'Invoice Register'!$G:$G,"<>")) -> 5322.74 | G31: =IF($A31="","",E31-F31) -> 0 | H31: =IF($A31="","",IF(E31>0,0,SUMIF('Cost Lines'!$C:$C,"*purpose #"&$A31&" *",'Cost Lines'!$F:$F))) -> 0 | I31: =IF(E31>0,IF(F31>=E31-0.005,"Paid",IF(F31>0,"Part paid","Invoiced, unpaid")),IF(H31>0,"Not yet invoiced","")) -> Paid | J31: Extended deck & shed base | K31: =IF(OR($A31="",$B31=""),"",$B$4-SUMIFS($E$8:$E$60,$B$8:$B$60,"<="&$B31)) -> -5729.42 | L31: Quote QUO-0031, placed and paid by phone 29 Sep. On its own larger than the whole pot.
A32: 25 | B32: 46245 | C32: TP materials — sand, white cement, Bosch blade | D32: Travis Perkins (Luke's account) — 1049231418 | E32: =IF($A32="","",SUMIFS('Invoice Register'!$F:$F,'Invoice Register'!$B:$B,"Contingency",'Invoice Register'!$L:$L,$A32)) -> 108.14 | F32: =IF($A32="","",SUMIFS('Invoice Register'!$F:$F,'Invoice Register'!$B:$B,"Contingency",'Invoice Register'!$L:$L,$A32,'Invoice Register'!$G:$G,"<>")) -> 108.14 | G32: =IF($A32="","",E32-F32) -> 0 | H32: =IF($A32="","",IF(E32>0,0,SUMIF('Cost Lines'!$C:$C,"*purpose #"&$A32&" *",'Cost Lines'!$F:$F))) -> 0 | I32: =IF(E32>0,IF(F32>=E32-0.005,"Paid",IF(F32>0,"Part paid","Invoiced, unpaid")),IF(H32>0,"Not yet invoiced","")) -> Paid | J32: Main deck | K32: =IF(OR($A32="",$B32=""),"",$B$4-SUMIFS($E$8:$E$60,$B$8:$B$60,"<="&$B32)) -> 4828.96 | L32: Travis Perkins invoice 1049231418. Paid from the £500 TP receipt of 11 Sep.
A33: 26 | B33: 46251 | C33: TP materials — ballast, building sand, 72 blocks | D33: Travis Perkins (Luke's account) — 1049595624 | E33: =IF($A33="","",SUMIFS('Invoice Register'!$F:$F,'Invoice Register'!$B:$B,"Contingency",'Invoice Register'!$L:$L,$A33)) -> 347.12 | F33: =IF($A33="","",SUMIFS('Invoice Register'!$F:$F,'Invoice Register'!$B:$B,"Contingency",'Invoice Register'!$L:$L,$A33,'Invoice Register'!$G:$G,"<>")) -> 347.12 | G33: =IF($A33="","",E33-F33) -> 0 | H33: =IF($A33="","",IF(E33>0,0,SUMIF('Cost Lines'!$C:$C,"*purpose #"&$A33&" *",'Cost Lines'!$F:$F))) -> 0 | I33: =IF(E33>0,IF(F33>=E33-0.005,"Paid",IF(F33>0,"Part paid","Invoiced, unpaid")),IF(H33>0,"Not yet invoiced","")) -> Paid | J33: Main deck | K33: =IF(OR($A33="",$B33=""),"",$B$4-SUMIFS($E$8:$E$60,$B$8:$B$60,"<="&$B33)) -> 4205.42 | L33: Travis Perkins invoice 1049595624. £247.01 paid from the £500 receipt; £100.11 balance paid by card 5 Oct.
A34: 27 | B34: 46268 | C34: TP materials — ballast x2, Mastercrete x10 | D34: Travis Perkins (Luke's account) — 1050655200 | E34: =IF($A34="","",SUMIFS('Invoice Register'!$F:$F,'Invoice Register'!$B:$B,"Contingency",'Invoice Register'!$L:$L,$A34)) -> 249.46 | F34: =IF($A34="","",SUMIFS('Invoice Register'!$F:$F,'Invoice Register'!$B:$B,"Contingency",'Invoice Register'!$L:$L,$A34,'Invoice Register'!$G:$G,"<>")) -> 249.46 | G34: =IF($A34="","",E34-F34) -> 0 | H34: =IF($A34="","",IF(E34>0,0,SUMIF('Cost Lines'!$C:$C,"*purpose #"&$A34&" *",'Cost Lines'!$F:$F))) -> 0 | I34: =IF(E34>0,IF(F34>=E34-0.005,"Paid",IF(F34>0,"Part paid","Invoiced, unpaid")),IF(H34>0,"Not yet invoiced","")) -> Paid | J34: Main deck | K34: =IF(OR($A34="",$B34=""),"",$B$4-SUMIFS($E$8:$E$60,$B$8:$B$60,"<="&$B34)) -> 3110.22 | L34: Travis Perkins invoice 1050655200.
... A37: 30 | B37: 46286 | C37: TP materials — 20 blocks | D37: Travis Perkins (Luke's account) — 1051708772 | E37: =IF($A37="","",SUMIFS('Invoice Register'!$F:$F,'Invoice Register'!$B:$B,"Contingency",'Invoice Register'!$L:$L,$A37)) -> 50.76 | F37: =IF($A37="","",SUMIFS('Invoice Register'!$F:$F,'Invoice Register'!$B:$B,"Contingency",'Invoice Register'!$L:$L,$A37,'Invoice Register'!$G:$G,"<>")) -> 50.76 | G37: =IF($A37="","",E37-F37) -> 0 | H37: =IF($A37="","",IF(E37>0,0,SUMIF('Cost Lines'!$C:$C,"*purpose #"&$A37&" *",'Cost Lines'!$F:$F))) -> 0 | I37: =IF(E37>0,IF(F37>=E37-0.005,"Paid",IF(F37>0,"Part paid","Invoiced, unpaid")),IF(H37>0,"Not yet invoiced","")) -> Paid | J37: Extended deck & shed base | K37: =IF(OR($A37="",$B37=""),"",$B$4-SUMIFS($E$8:$E$60,$B$8:$B$60,"<="&$B37)) -> -406.68 | L37: Travis Perkins invoice 1051708772.
A38: 31 | C38: Additional lead work — back-of-house gutters | D38: Luke (LG Building and Roofing) | E38: =IF($A38="","",SUMIFS('Invoice Register'!$F:$F,'Invoice Register'!$B:$B,"Contingency",'Invoice Register'!$L:$L,$A38)) -> 0 | F38: =IF($A38="","",SUMIFS('Invoice Register'!$F:$F,'Invoice Register'!$B:$B,"Contingency",'Invoice Register'!$L:$L,$A38,'Invoice Register'!$G:$G,"<>")) -> 0 | G38: =IF($A38="","",E38-F38) -> 0 | H38: =IF($A38="","",IF(E38>0,0,SUMIF('Cost Lines'!$C:$C,"*purpose #"&$A38&" *",'Cost Lines'!$F:$F))) -> 200 | I38: =IF(E38>0,IF(F38>=E38-0.005,"Paid",IF(F38>0,"Part paid","Invoiced, unpaid")),IF(H38>0,"Not yet invoiced","")) -> Not yet invoiced | J38: Roofline | K38: =IF(OR($A38="",$B38=""),"",$B$4-SUMIFS($E$8:$E$60,$B$8:$B$60,"<="&$B38)) | L38: Gantt task 1.5a, part of Gate 2. Chase lead into the walls so the gutters work properly. Luke's estimate about £200 (2 Oct), work completed Fri 16 Oct (lead flashing confirmed included); awaiting Luke's invoice.
A39: 32 | B39: 46304 | C39: Additional deck labour — extended deck & shed base | D39: Luke (LG Building and Roofing) — INV-0293 | E39: =IF($A39="","",SUMIFS('Invoice Register'!$F:$F,'Invoice Register'!$B:$B,"Contingency",'Invoice Register'!$L:$L,$A39)) -> 1050 | F39: =IF($A39="","",SUMIFS('Invoice Register'!$F:$F,'Invoice Register'!$B:$B,"Contingency",'Invoice Register'!$L:$L,$A39,'Invoice Register'!$G:$G,"<>")) -> 1050 | G39: =IF($A39="","",E39-F39) -> 0 | H39: =IF($A39="","",IF(E39>0,0,SUMIF('Cost Lines'!$C:$C,"*purpose #"&$A39&" *",'Cost Lines'!$F:$F))) -> 0 | I39: =IF($A39="","",IF(E39>0,IF(F39>=E39-0.005,"Paid",IF(F39>0,"Part paid","Invoiced, unpaid")),IF(H39>0,"Not yet invoiced",""))) -> Paid | J39: Extended deck & shed base | K39: =IF(OR($A39="",$B39=""),"",$B$4-SUMIFS($E$8:$E$60,$B$8:$B$60,"<="&$B39)) -> -7664.39 | L39: Part of LG INV-0293 (£1,850, 9 Oct): the £1,050 for the additional deck. The other £800 is the curves (#4). Paid 9 Oct by bank transfer. Separate from the £17,600 main decking labour draws.
A40: 33 | B40: 46301 | C40: Saw blades and drill bits — Toolstation | D40: Toolstation Ltd — YAC545477716 (bought by Luke) | E40: =IF($A40="","",SUMIFS('Invoice Register'!$F:$F,'Invoice Register'!$B:$B,"Contingency",'Invoice Register'!$L:$L,$A40)) -> 84.97 | F40: =IF($A40="","",SUMIFS('Invoice Register'!$F:$F,'Invoice Register'!$B:$B,"Contingency",'Invoice Register'!$L:$L,$A40,'Invoice Register'!$G:$G,"<>")) -> 84.97 | G40: =IF($A40="","",E40-F40) -> 0 | H40: =IF($A40="","",IF(E40>0,0,SUMIF('Cost Lines'!$C:$C,"*purpose #"&$A40&" *",'Cost Lines'!$F:$F))) -> 0 | I40: =IF($A40="","",IF(E40>0,IF(F40>=E40-0.005,"Paid",IF(F40>0,"Part paid","Invoiced, unpaid")),IF(H40>0,"Not yet invoiced",""))) -> Paid | J40: Main deck | K40: =IF(OR($A40="",$B40=""),"",$B$4-SUMIFS($E$8:$E$60,$B$8:$B$60,"<="&$B40)) -> -5814.39 | L40: Freud mitre saw blade, ROKTOR drill bits, DeWalt circular saw blade (£84.97). Luke paid by card 6 Oct; repaid in cash 13 Oct. Scope Main deck, although the tools will be used throughout the project.
A41: 34 | B41: 46314 | C41: Whole-house soft wash — Gorgeous Cleaning Services | D41: Gorgeous Cleaning Services | E41: =IF($A41="","",SUMIFS('Invoice Register'!$F:$F,'Invoice Register'!$B:$B,"Contingency",'Invoice Register'!$L:$L,$A41)) -> 1200 | F41: =IF($A41="","",SUMIFS('Invoice Register'!$F:$F,'Invoice Register'!$B:$B,"Contingency",'Invoice Register'!$L:$L,$A41,'Invoice Register'!$G:$G,"<>")) -> 1200 | G41: =IF($A41="","",E41-F41) -> 0 | H41: =IF($A41="","",IF(E41>0,0,SUMIF('Cost Lines'!$C:$C,"*purpose #"&$A41&" *",'Cost Lines'!$F:$F))) -> 0 | I41: =IF($A41="","",IF(E41>0,IF(F41>=E41-0.005,"Paid",IF(F41>0,"Part paid","Invoiced, unpaid")),IF(H41>0,"Not yet invoiced",""))) -> Paid | J41: Shared / site-wide | K41: =IF(OR($A41="",$B41=""),"",$B$4-SUMIFS($E$8:$E$60,$B$8:$B$60,"<="&$B41)) -> -10214.39 | L41: £1,200 cash, from Contingency, paid Mon 19 Oct. Gutters, soffits, roof tiles, roof solar panels, render, windows etc. Started and finished that day. Replaces the chimney + coping-only soft wash.
A42: 35 | B42: 46312 | C42: Driveway channel — water-softener waste | D42: Luke (LG Building and Roofing) — INV-0294 | E42: =IF($A42="","",SUMIFS('Invoice Register'!$F:$F,'Invoice Register'!$B:$B,"Contingency",'Invoice Register'!$L:$L,$A42)) -> 350 | F42: =IF($A42="","",SUMIFS('Invoice Register'!$F:$F,'Invoice Register'!$B:$B,"Contingency",'Invoice Register'!$L:$L,$A42,'Invoice Register'!$G:$G,"<>")) -> 350 | G42: =IF($A42="","",E42-F42) -> 0 | H42: =IF($A42="","",IF(E42>0,0,SUMIF('Cost Lines'!$C:$C,"*purpose #"&$A42&" *",'Cost Lines'!$F:$F))) -> 0 | I42: =IF($A42="","",IF(E42>0,IF(F42>=E42-0.005,"Paid",IF(F42>0,"Part paid","Invoiced, unpaid")),IF(H42>0,"Not yet invoiced",""))) -> Paid | J42: Driveway channel | K42: =IF(OR($A42="",$B42=""),"",$B$4-SUMIFS($E$8:$E$60,$B$8:$B$60,"<="&$B42)) -> -9014.39 | L42: Half a day, Luke and Max, 14 Oct (Gantt 3.1). Water-softener discharge connected to natural drainage; cobbles reinstated; discharge confirmed working. £350 of LG INV-0294 (£1,350), paid 17 Oct by bank transfer.
A43: 36 | B43: 46312 | C43: Extra decking labour — extended deck & shed base | D43: Luke (LG Building and Roofing) — INV-0294 | E43: =IF($A43="","",SUMIFS('Invoice Register'!$F:$F,'Invoice Register'!$B:$B,"Contingency",'Invoice Register'!$L:$L,$A43)) -> 1000 | F43: =IF($A43="","",SUMIFS('Invoice Register'!$F:$F,'Invoice Register'!$B:$B,"Contingency",'Invoice Register'!$L:$L,$A43,'Invoice Register'!$G:$G,"<>")) -> 1000 | G43: =IF($A43="","",E43-F43) -> 0 | H43: =IF($A43="","",IF(E43>0,0,SUMIF('Cost Lines'!$C:$C,"*purpose #"&$A43&" *",'Cost Lines'!$F:$F))) -> 0 | I43: =IF($A43="","",IF(E43>0,IF(F43>=E43-0.005,"Paid",IF(F43>0,"Part paid","Invoiced, unpaid")),IF(H43>0,"Not yet invoiced",""))) -> Paid | J43: Extended deck & shed base | K43: =IF(OR($A43="",$B43=""),"",$B$4-SUMIFS($E$8:$E$60,$B$8:$B$60,"<="&$B43)) -> -9014.39 | L43: £1,000 of LG INV-0294 (£1,350), paid 17 Oct by bank transfer. Extra decking labour as discussed. No further extended-deck labour agreed yet.
...

Sheet Scope View
A1: Scope View — what the money was for
A2: Cost centre = which budget pays; Scope = what it was for. Source: the Scope column on the Invoice Register. Amounts invoiced, inc VAT. Scope tags on Travis Perkins invoices are INFERRED: Luke's 2 Oct update says only 1 day (2 people) has been spent on the extended deck so far, so only TP invoices from 21 Sep are treated as extended; earlier ones are main deck. Digger/dumper hire served both and is not split. Confirm with Luke. LG INV-0293 (9 Oct) is split: £800 curves (Main deck) and £1,050 additional deck (Extended deck & shed base). Toolstation saw blades (13 Oct, £84.97) are tagged Main deck although used throughout. LG INV-0294 (17 Oct) is split: £350 driveway channel (new scope, Driveway channel) and £1,000 extra decking labour (Extended deck & shed base). Pipe lagging (20 Oct, £177.58) is tagged Shared / site-wide (main deck). V4 QUO-0040 (22 Oct, £1,268) is tagged Extended deck & shed base, though some Plas-Pro will likely be used on the main decking. New scope "New shed & electrics" (workstream 8) covers the shed, its installation and the electrics; nothing invoiced against it yet.
A4: A. Invoiced by scope and cost centre
A5: Scope | B5: Decking materials (V4) | C5: Decking labour | D5: Contingency | E5: Roofline works | F5: Chimney repair | G5: Coping stones repair | H5: Materials (pooled) | I5: Rubbish removal (pooled skips) | J5: Total invoiced £ | K5: Total paid £ | L5: Unpaid £
